Workbook

Sheet Menu

Sheet Resumo de Custo
A2: Menu | E2: Resumo de Custo | K2: =TODAY() -> 46101 | L2: =K3-K2 -> -95
K3: 46006
A4: Horas Trabalhadas
A5: 220
B6: Janeiro | L6: Fevereiro | V6: Março | AF6: Abril | AP6: Maio | AZ6: Junho | BJ6: Julho | BT6: Agosto | CD6: Setembro | CN6: Outubro | CX6: Novembro | DH6: Dezembro
A7: Linha | B7: Produto Químico | C7: M.O.D | D7: M.O.I | E7: Custo Variáveis | F7: Outros Custos | G7: Transporte | H7: Manutenção | I7: Investimentos | J7: Total | K7: Custo Hora | L7: Produto Químico | M7: M.O.D | N7: M.O.I | O7: Custo Variáveis | P7: Outros Custos | Q7: Transporte | R7: Manutenção | S7: Investimentos | T7: Total | U7: Custo Hora | V7: Produto Químico | W7: M.O.D | X7: M.O.I | Y7: Custo Variáveis | Z7: Outros Custos | AA7: Transporte | AB7: Manutenção | AC7: Investimentos | AD7: Total | AE7: Custo Hora | AF7: Produto Químico | AG7: M.O.D | AH7: M.O.I | AI7: Custo Variáveis | AJ7: Outros Custos | AK7: Transporte | AL7: Manutenção | AM7: Investimentos | AN7: Total | AO7: Custo Hora | AP7: Produto Químico | AQ7: M.O.D | AR7: M.O.I | AS7: Custo Variáveis | AT7: Outros Custos | AU7: Transporte | AV7: Manutenção | AW7: Investimentos | AX7: Total | AY7: Custo Hora | AZ7: Produto Químico | BA7: M.O.D | BB7: M.O.I | BC7: Custo Variáveis | BD7: Outros Custos | BE7: Transporte | BF7: Manutenção | BG7: Investimentos | BH7: Total | BI7: Custo Hora | BJ7: Produto Químico | BK7: M.O.D | BL7: M.O.I | BM7: Custo Variáveis | BN7: Outros Custos | BO7: Transporte | BP7: Manutenção | BQ7: Investimentos | BR7: Total | BS7: Custo Hora | BT7: Produto Químico | BU7: M.O.D | BV7: M.O.I | BW7: Custo Variáveis | BX7: Outros Custos | BY7: Transporte | BZ7: Manutenção | CA7: Investimentos | CB7: Total | CC7: Custo Hora | CD7: Produto Químico | CE7: M.O.D | CF7: M.O.I | CG7: Custo Variáveis | CH7: Outros Custos | CI7: Transporte | CJ7: Manutenção | CK7: Investimentos | CL7: Total | CM7: Custo Hora | CN7: Produto Químico | CO7: M.O.D | CP7: M.O.I | CQ7: Custo Variáveis | CR7: Outros Custos | CS7: Transporte | CT7: Manutenção | CU7: Investimentos | CV7: Total | CW7: Custo Hora | CX7: Produto Químico | CY7: M.O.D | CZ7: M.O.I | DA7: Custo Variáveis | DB7: Outros Custos | DC7: Transporte | DD7: Manutenção | DE7: Investimentos | DF7: Total | DG7: Custo Hora | DH7: Produto Químico | DI7: M.O.D | DJ7: M.O.I | DK7: Custo Variáveis | DL7: Outros Custos | DM7: Transporte | DN7: Manutenção | DO7: Investimentos | DP7: Total | DQ7: Custo Hora | DS7: Jan | DT7: Fev | DU7: Mar | DV7: Abr | DW7: Mai | DX7: Jun | DY7: Jul | DZ7: Ago | EA7: Set | EB7: Out | EC7: Nov | ED7: Dez | EF7: Jan | EG7: Fev | EH7: Mar | EI7: Abr | EJ7: Mai | EK7: Jun | EL7: Jul | EM7: Ago | EN7: Set | EO7: Out | EP7: Nov | EQ7: Dez
A8: Pré Tratamento | B8: ='Pré Tratamento'!G15 -> 0 | C8: ='Resumo M.O'!$C$14 -> 1490.6153 | D8: ='Resumo M.O'!$C$29 -> 2265.2114 | E8: ='Resumo Custos Variáveis'!$E$21 -> 0 | F8: ='Outros Custos'!$C$31 -> 0 | G8: =Transporte!$C$20 -> 0 | H8: =Manutenção!$C$21 -> 0 | I8: =Investimentos!G10 -> 0 | J8: =SUM(B8:I8) -> 3755.8267 | K8: =IF($L$2>=1,J8/$A$5,0) -> 0 | L8: ='Pré Tratamento'!J15 -> 0 | M8: ='Resumo M.O'!$D$14 -> 1490.6153 | N8: ='Resumo M.O'!$D$29 -> 2265.2114 | O8: ='Resumo Custos Variáveis'!$F$21 -> 0 | P8: ='Outros Custos'!$D$31 -> 0 | Q8: =Transporte!$D$20 -> 0 | R8: =Manutenção!$D$21 -> 0 | S8: =I8 -> 0 | T8: =SUM(L8:S8) -> 3755.8267 | U8: =IF($L$2>=1,T8/$A$5,0) -> 0 | V8: ='Pré Tratamento'!M15 -> 4019.75 | W8: ='Resumo M.O'!$E$14 -> 1490.6153 | X8: ='Resumo M.O'!$E$29 -> 2265.2114 | Y8: ='Resumo Custos Variáveis'!$G$21 -> 2404.5263 | Z8: ='Outros Custos'!$E$31 -> 0 | AA8: =Transporte!$E$20 -> 0 | AB8: =Manutenção!$E$21 -> 0 | AC8: =S8 -> 0 | AD8: =SUM(V8:AC8) -> 10180.103 | AE8: =IF($L$2>=1,AD8/$A$5,0) -> 0 | AF8: ='Pré Tratamento'!P15 -> 2903.5 | AG8: ='Resumo M.O'!$F$14 -> 1490.6153 | AH8: ='Resumo M.O'!$F$29 -> 2265.2114 | AI8: ='Resumo Custos Variáveis'!$H$21 -> 1573.8421 | AJ8: ='Outros Custos'!$F$31 -> 0 | AK8: =Transporte!$F$20 -> 0 | AL8: =Manutenção!$F$21 -> 0 | AM8: =AC8 -> 0 | AN8: =SUM(AF8:AM8) -> 8233.1688 | AO8: =IF(L2>=1,AN8/$A$5,0) -> 0 | AP8: ='Pré Tratamento'!S15 -> 129 | AQ8: ='Resumo M.O'!$G$14 -> 1490.6153 | AR8: ='Resumo M.O'!$G$29 -> 2265.2114 | AS8: ='Resumo Custos Variáveis'!$I$21 -> 0 | AT8: ='Outros Custos'!$G$31 -> 0 | AU8: =Transporte!$G$20 -> 0 | AV8: =Manutenção!$G$21 -> 0 | AW8: =AM8 -> 0 | AX8: =SUM(AP8:AW8) -> 3884.8267 | AY8: =IF(L2>=1,AX8/$A$5,0) -> 0 | AZ8: ='Pré Tratamento'!V15 -> 258 | BA8: ='Resumo M.O'!$H$14 -> 1490.6153 | BB8: ='Resumo M.O'!$H$29 -> 2265.2114 | BC8: ='Resumo Custos Variáveis'!$J$21 -> 0 | BD8: ='Outros Custos'!$H$31 -> 0 | BE8: =Transporte!$H$20 -> 0 | BF8: =Manutenção!$H$21 -> 3061.5385 | BG8: =AW8 -> 0 | BH8: =SUM(AZ8:BG8) -> 7075.3651 | BI8: =IF(L2>=1,BH8/$A$5,0) -> 0 | BJ8: ='Pré Tratamento'!Y15 -> 0 | BK8: ='Resumo M.O'!$I$14 -> 1490.6153 | BL8: ='Resumo M.O'!$I$29 -> 2265.2114 | BM8: ='Resumo Custos Variáveis'!$K$21 -> 0 | BN8: ='Outros Custos'!$I$31 -> 0 | BO8: =Transporte!$I$20 -> 0 | BP8: =Manutenção!$I$21 -> 3030.7692 | BQ8: =BG8 -> 0 | BR8: =SUM(BJ8:BQ8) -> 6786.5959 | BS8: =IF(L2>=1,BR8/$A$5,0) -> 0 | BT8: ='Pré Tratamento'!AB15 -> 0 | BU8: ='Resumo M.O'!$J$14 -> 1490.6153 | BV8: ='Resumo M.O'!$J$29 -> 2265.2114 | BW8: ='Resumo Custos Variáveis'!$L$21 -> 0 | BX8: ='Outros Custos'!$J$31 -> 0 | BY8: =Transporte!$J$20 -> 0 | BZ8: =Manutenção!$J$21 -> 0 | CA8: =BQ8 -> 0 | CB8: =SUM(BT8:CA8) -> 3755.8267 | CC8: =IF(L2>=1,CB8/$A$5,0) -> 0 | CD8: ='Pré Tratamento'!AE15 -> 0 | CE8: ='Resumo M.O'!$K$14 -> 1490.6153 | CF8: ='Resumo M.O'!$K$29 -> 2265.2114 | CG8: ='Resumo Custos Variáveis'!$M$21 -> 0 | CH8: ='Outros Custos'!$K$31 -> 0 | CI8: =Transporte!$K$20 -> 0 | CJ8: =Manutenção!$K$21 -> 0 | CK8: =CA8 -> 0 | CL8: =SUM(CD8:CK8) -> 3755.8267 | CM8: =IF(L2>=1,CL8/$A$5,0) -> 0 | CN8: ='Pré Tratamento'!AH15 -> 0 | CO8: ='Resumo M.O'!$L$14 -> 1490.6153 | CP8: ='Resumo M.O'!$L$29 -> 2265.2114 | CQ8: ='Resumo Custos Variáveis'!$N$21 -> 0 | CR8: ='Outros Custos'!$L$31 -> 0 | CS8: =Transporte!$L$20 -> 0 | CT8: =Manutenção!$L$21 -> 0 | CU8: =CK8 -> 0 | CV8: =SUM(CN8:CU8) -> 3755.8267 | CW8: =IF(L2>=1,CV8/$A$5,0) -> 0 | CX8: ='Pré Tratamento'!AK15 -> 0 | CY8: ='Resumo M.O'!$M$14 -> 1490.6153 | CZ8: ='Resumo M.O'!$M$29 -> 2265.2114 | DA8: ='Resumo Custos Variáveis'!$O$21 -> 0 | DB8: ='Outros Custos'!$M$31 -> 0 | DC8: =Transporte!$M$20 -> 0 | DD8: =Manutenção!$M$21 -> 0 | DE8: =CU8 -> 0 | DF8: =SUM(CX8:DE8) -> 3755.8267 | DG8: =IF(L2>=1,DF8/$A$5,0) -> 0 | DH8: ='Pré Tratamento'!AN15 -> 0 | DI8: ='Resumo M.O'!$N$14 -> 1490.6153 | DJ8: ='Resumo M.O'!$N$29 -> 2265.2114 | DK8: ='Resumo Custos Variáveis'!$P$21 -> 0 | DL8: ='Outros Custos'!$N$31 -> 0 | DM8: =Transporte!$N$20 -> 0 | DN8: =Manutenção!$N$21 -> 0 | DO8: =DE8 -> 0 | DP8: =SUM(DH8:DO8) -> 3755.8267 | DQ8: =IF(L2>=1,DP8/$A$5,0) -> 0 | DS8: =K8 -> 0 | DT8: =U8 -> 0 | DU8: =AE8 -> 0 | DV8: =AO8 -> 0 | DW8: =AY8 -> 0 | DX8: =BI8 -> 0 | DY8: =BS8 -> 0 | DZ8: =CC8 -> 0 | EA8: =CM8 -> 0 | EB8: =CW8 -> 0 | EC8: =DG8 -> 0 | ED8: =DQ8 -> 0 | EF8: =B8/$A$5 -> 0 | EG8: =L8/$A$5 -> 0 | EH8: =V8/$A$5 -> 18.271591 | EI8: =AF8/$A$5 -> 13.197727 | EJ8: =AP8/$A$5 -> 0.58636364 | EK8: =AZ8/$A$5 -> 1.1727273 | EL8: =BJ8/$A$5 -> 0 | EM8: =BT8/$A$5 -> 0 | EN8: =CD8/$A$5 -> 0 | EO8: =CN8/$A$5 -> 0 | EP8: =CX8/$A$5 -> 0 | EQ8: =DH8/$A$5 -> 0
A9: Cobre Alcalino | B9: ='Cobre Alcalino'!G16 -> 0 | C9: ='Resumo M.O'!$C$14 -> 1490.6153 | D9: ='Resumo M.O'!$C$29 -> 2265.2114 | E9: ='Resumo Custos Variáveis'!$E$21 -> 0 | F9: ='Outros Custos'!$C$31 -> 0 | G9: =Transporte!$C$20 -> 0 | H9: =Manutenção!$C$21 -> 0 | I9: =Investimentos!G14 -> 0 | J9: =SUM(B9:I9) -> 3755.8267 | K9: =IF($L$2>=1,J9/$A$5,0) -> 0 | L9: ='Cobre Alcalino'!J16 -> 0 | M9: ='Resumo M.O'!$D$14 -> 1490.6153 | N9: ='Resumo M.O'!$D$29 -> 2265.2114 | O9: ='Resumo Custos Variáveis'!$F$21 -> 0 | P9: ='Outros Custos'!$D$31 -> 0 | Q9: =Transporte!$D$20 -> 0 | R9: =Manutenção!$D$21 -> 0 | S9: =I9 -> 0 | T9: =SUM(L9:S9) -> 3755.8267 | U9: =IF($L$2>=1,T9/$A$5,0) -> 0 | V9: ='Cobre Alcalino'!M16 -> 13969.47 | W9: ='Resumo M.O'!$E$14 -> 1490.6153 | X9: ='Resumo M.O'!$E$29 -> 2265.2114 | Y9: ='Resumo Custos Variáveis'!$G$21 -> 2404.5263 | Z9: ='Outros Custos'!$E$31 -> 0 | AA9: =Transporte!$E$20 -> 0 | AB9: =Manutenção!$E$21 -> 0 | AC9: =S9 -> 0 | AD9: =SUM(V9:AC9) -> 20129.823 | AE9: =IF($L$2>=1,AD9/$A$5,0) -> 0 | AF9: ='Cobre Alcalino'!P16 -> 13481.89 | AG9: ='Resumo M.O'!$F$14 -> 1490.6153 | AH9: ='Resumo M.O'!$F$29 -> 2265.2114 | AI9: ='Resumo Custos Variáveis'!$H$21 -> 1573.8421 | AJ9: ='Outros Custos'!$F$31 -> 0 | AK9: =Transporte!$F$20 -> 0 | AL9: =Manutenção!$F$21 -> 0 | AM9: =AC9 -> 0 | AN9: =SUM(AF9:AM9) -> 18811.559 | AO9: =IF(L2>=1,AN9/$A$5,0) -> 0 | AP9: ='Cobre Alcalino'!S16 -> 669.8 | AQ9: ='Resumo M.O'!$G$14 -> 1490.6153 | AR9: ='Resumo M.O'!$G$29 -> 2265.2114 | AS9: ='Resumo Custos Variáveis'!$I$21 -> 0 | AT9: ='Outros Custos'!$G$31 -> 0 | AU9: =Transporte!$G$20 -> 0 | AV9: =Manutenção!$G$21 -> 0 | AW9: =AM9 -> 0 | AX9: =SUM(AP9:AW9) -> 4425.6267 | AY9: =IF(L2>=1,AX9/$A$5,0) -> 0 | AZ9: ='Cobre Alcalino'!V16 -> 669.8 | BA9: ='Resumo M.O'!$H$14 -> 1490.6153 | BB9: ='Resumo M.O'!$H$29 -> 2265.2114 | BC9: ='Resumo Custos Variáveis'!$J$21 -> 0 | BD9: ='Outros Custos'!$H$31 -> 0 | BE9: =Transporte!$H$20 -> 0 | BF9: =Manutenção!$H$21 -> 3061.5385 | BG9: =AW9 -> 0 | BH9: =SUM(AZ9:BG9) -> 7487.1651 | BI9: =IF(L2>=1,BH9/$A$5,0) -> 0 | BJ9: ='Cobre Alcalino'!Y16 -> 0 | BK9: ='Resumo M.O'!$I$14 -> 1490.6153 | BL9: ='Resumo M.O'!$I$29 -> 2265.2114 | BM9: ='Resumo Custos Variáveis'!$K$21 -> 0 | BN9: ='Outros Custos'!$I$31 -> 0 | BO9: =Transporte!$I$20 -> 0 | BP9: =Manutenção!$I$21 -> 3030.7692 | BQ9: =BG9 -> 0 | BR9: =SUM(BJ9:BQ9) -> 6786.5959 | BS9: =IF(L2>=1,BR9/$A$5,0) -> 0 | BT9: ='Cobre Alcalino'!AB16 -> 0 | BU9: ='Resumo M.O'!$J$14 -> 1490.6153 | BV9: ='Resumo M.O'!$J$29 -> 2265.2114 | BW9: ='Resumo Custos Variáveis'!$L$21 -> 0 | BX9: ='Outros Custos'!$J$31 -> 0 | BY9: =Transporte!$J$20 -> 0 | BZ9: =Manutenção!$J$21 -> 0 | CA9: =BQ9 -> 0 | CB9: =SUM(BT9:CA9) -> 3755.8267 | CC9: =IF(L2>=1,CB9/$A$5,0) -> 0 | CD9: ='Cobre Alcalino'!AE16 -> 0 | CE9: ='Resumo M.O'!$K$14 -> 1490.6153 | CF9: ='Resumo M.O'!$K$29 -> 2265.2114 | CG9: ='Resumo Custos Variáveis'!$M$21 -> 0 | CH9: ='Outros Custos'!$K$31 -> 0 | CI9: =Transporte!$K$20 -> 0 | CJ9: =Manutenção!$K$21 -> 0 | CK9: =CA9 -> 0 | CL9: =SUM(CD9:CK9) -> 3755.8267 | CM9: =IF(L2>=1,CL9/$A$5,0) -> 0 | CN9: ='Cobre Alcalino'!AH16 -> 0 | CO9: ='Resumo M.O'!$L$14 -> 1490.6153 | CP9: ='Resumo M.O'!$L$29 -> 2265.2114 | CQ9: ='Resumo Custos Variáveis'!$N$21 -> 0 | CR9: ='Outros Custos'!$L$31 -> 0 | CS9: =Transporte!$L$20 -> 0 | CT9: =Manutenção!$L$21 -> 0 | CU9: =CK9 -> 0 | CV9: =SUM(CN9:CU9) -> 3755.8267 | CW9: =IF(L2>=1,CV9/$A$5,0) -> 0 | CX9: ='Cobre Alcalino'!AK16 -> 0 | CY9: ='Resumo M.O'!$M$14 -> 1490.6153 | CZ9: ='Resumo M.O'!$M$29 -> 2265.2114 | DA9: ='Resumo Custos Variáveis'!$O$21 -> 0 | DB9: ='Outros Custos'!$M$31 -> 0 | DC9: =Transporte!$M$20 -> 0 | DD9: =Manutenção!$M$21 -> 0 | DE9: =CU9 -> 0 | DF9: =SUM(CX9:DE9) -> 3755.8267 | DG9: =IF(L2>=1,DF9/$A$5,0) -> 0 | DH9: ='Cobre Alcalino'!AN16 -> 0 | DI9: ='Resumo M.O'!$N$14 -> 1490.6153 | DJ9: ='Resumo M.O'!$N$29 -> 2265.2114 | DK9: ='Resumo Custos Variáveis'!$P$21 -> 0 | DL9: ='Outros Custos'!$N$31 -> 0 | DM9: =Transporte!$N$20 -> 0 | DN9: =Manutenção!$N$21 -> 0 | DO9: =DE9 -> 0 | DP9: =SUM(DH9:DO9) -> 3755.8267 | DQ9: =IF(L2>=1,DP9/$A$5,0) -> 0 | DS9: =K9 -> 0 | DT9: =U9 -> 0 | DU9: =AE9 -> 0 | DV9: =AO9 -> 0 | DW9: =AY9 -> 0 | DX9: =BI9 -> 0 | DY9: =BS9 -> 0 | DZ9: =CC9 -> 0 | EA9: =CM9 -> 0 | EB9: =CW9 -> 0 | EC9: =DG9 -> 0 | ED9: =DQ9 -> 0 | EF9: =B9/$A$5 -> 0 | EG9: =L9/$A$5 -> 0 | EH9: =V9/$A$5 -> 63.497591 | EI9: =AF9/$A$5 -> 61.281318 | EJ9: =AP9/$A$5 -> 3.0445455 | EK9: =AZ9/$A$5 -> 3.0445455 | EL9: =BJ9/$A$5 -> 0 | EM9: =BT9/$A$5 -> 0 | EN9: =CD9/$A$5 -> 0 | EO9: =CN9/$A$5 -> 0 | EP9: =CX9/$A$5 -> 0 | EQ9: =DH9/$A$5 -> 0
A10: Níquel Strik | B10: ='Níquel Strik'!G15 -> 0 | C10: ='Resumo M.O'!$C$14 -> 1490.6153 | D10: ='Resumo M.O'!$C$29 -> 2265.2114 | E10: ='Resumo Custos Variáveis'!$E$21 -> 0 | F10: ='Outros Custos'!$C$31 -> 0 | G10: =Transporte!$C$20 -> 0 | H10: =Manutenção!$C$21 -> 0 | I10: =Investimentos!G18 -> 0 | J10: =SUM(B10:I10) -> 3755.8267 | K10: =IF($L$2>=1,J10/$A$5,0) -> 0 | L10: ='Níquel Strik'!J15 -> 0 | M10: ='Resumo M.O'!$D$14 -> 1490.6153 | N10: ='Resumo M.O'!$D$29 -> 2265.2114 | O10: ='Resumo Custos Variáveis'!$F$21 -> 0 | P10: ='Outros Custos'!$D$31 -> 0 | Q10: =Transporte!$D$20 -> 0 | R10: =Manutenção!$D$21 -> 0 | S10: =I10 -> 0 | T10: =SUM(L10:S10) -> 3755.8267 | U10: =IF($L$2>=1,T10/$A$5,0) -> 0 | V10: ='Níquel Strik'!M15 -> 7666.505 | W10: ='Resumo M.O'!$E$14 -> 1490.6153 | X10: ='Resumo M.O'!$E$29 -> 2265.2114 | Y10: ='Resumo Custos Variáveis'!$G$21 -> 2404.5263 | Z10: ='Outros Custos'!$E$31 -> 0 | AA10: =Transporte!$E$20 -> 0 | AB10: =Manutenção!$E$21 -> 0 | AC10: =S10 -> 0 | AD10: =SUM(V10:AC10) -> 13826.858 | AE10: =IF($L$2>=1,AD10/$A$5,0) -> 0 | AF10: ='Níquel Strik'!P15 -> 3351.28 | AG10: ='Resumo M.O'!$F$14 -> 1490.6153 | AH10: ='Resumo M.O'!$F$29 -> 2265.2114 | AI10: ='Resumo Custos Variáveis'!$H$21 -> 1573.8421 | AJ10: ='Outros Custos'!$F$31 -> 0 | AK10: =Transporte!$F$20 -> 0 | AL10: =Manutenção!$F$21 -> 0 | AM10: =AC10 -> 0 | AN10: =SUM(AF10:AM10) -> 8680.9488 | AO10: =IF(L2>=1,AN10/$A$5,0) -> 0 | AP10: ='Níquel Strik'!S15 -> 5959.8 | AQ10: ='Resumo M.O'!$G$14 -> 1490.6153 | AR10: ='Resumo M.O'!$G$29 -> 2265.2114 | AS10: ='Resumo Custos Variáveis'!$I$21 -> 0 | AT10: ='Outros Custos'!$G$31 -> 0 | AU10: =Transporte!$G$20 -> 0 | AV10: =Manutenção!$G$21 -> 0 | AW10: =AM10 -> 0 | AX10: =SUM(AP10:AW10) -> 9715.6267 | AY10: =IF(L2>=1,AX10/$A$5,0) -> 0 | AZ10: ='Níquel Strik'!V15 -> 5959.8 | BA10: ='Resumo M.O'!$H$14 -> 1490.6153 | BB10: ='Resumo M.O'!$H$29 -> 2265.2114 | BC10: ='Resumo Custos Variáveis'!$J$21 -> 0 | BD10: ='Outros Custos'!$H$31 -> 0 | BE10: =Transporte!$H$20 -> 0 | BF10: =Manutenção!$H$21 -> 3061.5385 | BG10: =AW10 -> 0 | BH10: =SUM(AZ10:BG10) -> 12777.165 | BI10: =IF(L2>=1,BH10/$A$5,0) -> 0 | BJ10: ='Níquel Strik'!Y15 -> 0 | BK10: ='Resumo M.O'!$I$14 -> 1490.6153 | BL10: ='Resumo M.O'!$I$29 -> 2265.2114 | BM10: ='Resumo Custos Variáveis'!$K$21 -> 0 | BN10: ='Outros Custos'!$I$31 -> 0 | BO10: =Transporte!$I$20 -> 0 | BP10: =Manutenção!$I$21 -> 3030.7692 | BQ10: =BG10 -> 0 | BR10: =SUM(BJ10:BQ10) -> 6786.5959 | BS10: =IF(L2>=1,BR10/$A$5,0) -> 0 | BT10: ='Níquel Strik'!AB15 -> 0 | BU10: ='Resumo M.O'!$J$14 -> 1490.6153 | BV10: ='Resumo M.O'!$J$29 -> 2265.2114 | BW10: ='Resumo Custos Variáveis'!$L$21 -> 0 | BX10: ='Outros Custos'!$J$31 -> 0 | BY10: =Transporte!$J$20 -> 0 | BZ10: =Manutenção!$J$21 -> 0 | CA10: =BQ10 -> 0 | CB10: =SUM(BT10:CA10) -> 3755.8267 | CC10: =IF(L2>=1,CB10/$A$5,0) -> 0 | CD10: ='Níquel Strik'!AE15 -> 0 | CE10: ='Resumo M.O'!$K$14 -> 1490.6153 | CF10: ='Resumo M.O'!$K$29 -> 2265.2114 | CG10: ='Resumo Custos Variáveis'!$M$21 -> 0 | CH10: ='Outros Custos'!$K$31 -> 0 | CI10: =Transporte!$K$20 -> 0 | CJ10: =Manutenção!$K$21 -> 0 | CK10: =CA10 -> 0 | CL10: =SUM(CD10:CK10) -> 3755.8267 | CM10: =IF(L2>=1,CL10/$A$5,0) -> 0 | CN10: ='Níquel Strik'!AH15 -> 0 | CO10: ='Resumo M.O'!$L$14 -> 1490.6153 | CP10: ='Resumo M.O'!$L$29 -> 2265.2114 | CQ10: ='Resumo Custos Variáveis'!$N$21 -> 0 | CR10: ='Outros Custos'!$L$31 -> 0 | CS10: =Transporte!$L$20 -> 0 | CT10: =Manutenção!$L$21 -> 0 | CU10: =CK10 -> 0 | CV10: =SUM(CN10:CU10) -> 3755.8267 | CW10: =IF(L2>=1,CV10/$A$5,0) -> 0 | CX10: ='Níquel Strik'!AK15 -> 0 | CY10: ='Resumo M.O'!$M$14 -> 1490.6153 | CZ10: ='Resumo M.O'!$M$29 -> 2265.2114 | DA10: ='Resumo Custos Variáveis'!$O$21 -> 0 | DB10: ='Outros Custos'!$M$31 -> 0 | DC10: =Transporte!$M$20 -> 0 | DD10: =Manutenção!$M$21 -> 0 | DE10: =CU10 -> 0 | DF10: =SUM(CX10:DE10) -> 3755.8267 | DG10: =IF(L2>=1,DF10/$A$5,0) -> 0 | DH10: ='Níquel Strik'!AN15 -> 0 | DI10: ='Resumo M.O'!$N$14 -> 1490.6153 | DJ10: ='Resumo M.O'!$N$29 -> 2265.2114 | DK10: ='Resumo Custos Variáveis'!$P$21 -> 0 | DL10: ='Outros Custos'!$N$31 -> 0 | DM10: =Transporte!$N$20 -> 0 | DN10: =Manutenção!$N$21 -> 0 | DO10: =DE10 -> 0 | DP10: =SUM(DH10:DO10) -> 3755.8267 | DQ10: =IF(L2>=1,DP10/$A$5,0) -> 0 | DS10: =K10 -> 0 | DT10: =U10 -> 0 | DU10: =AE10 -> 0 | DV10: =AO10 -> 0 | DW10: =AY10 -> 0 | DX10: =BI10 -> 0 | DY10: =BS10 -> 0 | DZ10: =CC10 -> 0 | EA10: =CM10 -> 0 | EB10: =CW10 -> 0 | EC10: =DG10 -> 0 | ED10: =DQ10 -> 0 | EF10: =B10/$A$5 -> 0 | EG10: =L10/$A$5 -> 0 | EH10: =V10/$A$5 -> 34.84775 | EI10: =AF10/$A$5 -> 15.233091 | EJ10: =AP10/$A$5 -> 27.09 | EK10: =AZ10/$A$5 -> 27.09 | EL10: =BJ10/$A$5 -> 0 | EM10: =BT10/$A$5 -> 0 | EN10: =CD10/$A$5 -> 0 | EO10: =CN10/$A$5 -> 0 | EP10: =CX10/$A$5 -> 0 | EQ10: =DH10/$A$5 -> 0
A11: Cobre Ácido | B11: =+'Cobre Ácido'!G15 -> 0 | C11: ='Resumo M.O'!$C$14 -> 1490.6153 | D11: ='Resumo M.O'!$C$29 -> 2265.2114 | E11: ='Resumo Custos Variáveis'!$E$21 -> 0 | F11: ='Outros Custos'!$C$31 -> 0 | G11: =Transporte!$C$20 -> 0 | H11: =Manutenção!$C$21 -> 0 | I11: =Investimentos!G24 -> 0 | J11: =SUM(B11:I11) -> 3755.8267 | K11: =IF($L$2>=1,J11/$A$5,0) -> 0 | L11: ='Cobre Ácido'!J15 -> 0 | M11: ='Resumo M.O'!$D$14 -> 1490.6153 | N11: ='Resumo M.O'!$D$29 -> 2265.2114 | O11: ='Resumo Custos Variáveis'!$F$21 -> 0 | P11: ='Outros Custos'!$D$31 -> 0 | Q11: =Transporte!$D$20 -> 0 | R11: =Manutenção!$D$21 -> 0 | S11: =I11 -> 0 | T11: =SUM(L11:S11) -> 3755.8267 | U11: =IF($L$2>=1,T11/$A$5,0) -> 0 | V11: ='Cobre Ácido'!M15 -> 25728.56 | W11: ='Resumo M.O'!$E$14 -> 1490.6153 | X11: ='Resumo M.O'!$E$29 -> 2265.2114 | Y11: ='Resumo Custos Variáveis'!$G$21 -> 2404.5263 | Z11: ='Outros Custos'!$E$31 -> 0 | AA11: =Transporte!$E$20 -> 0 | AB11: =Manutenção!$E$21 -> 0 | AC11: =S11 -> 0 | AD11: =SUM(V11:AC11) -> 31888.913 | AE11: =IF($L$2>=1,AD11/$A$5,0) -> 0 | AF11: ='Cobre Ácido'!P15 -> 22757.76 | AG11: ='Resumo M.O'!$F$14 -> 1490.6153 | AH11: ='Resumo M.O'!$F$29 -> 2265.2114 | AI11: ='Resumo Custos Variáveis'!$H$21 -> 1573.8421 | AJ11: ='Outros Custos'!$F$31 -> 0 | AK11: =Transporte!$F$20 -> 0 | AL11: =Manutenção!$F$21 -> 0 | AM11: =AC11 -> 0 | AN11: =SUM(AF11:AM11) -> 28087.429 | AO11: =IF(L2>=1,AN11/$A$5,0) -> 0 | AP11: ='Cobre Ácido'!S15 -> 1926 | AQ11: ='Resumo M.O'!$G$14 -> 1490.6153 | AR11: ='Resumo M.O'!$G$29 -> 2265.2114 | AS11: ='Resumo Custos Variáveis'!$I$21 -> 0 | AT11: ='Outros Custos'!$G$31 -> 0 | AU11: =Transporte!$G$20 -> 0 | AV11: =Manutenção!$G$21 -> 0 | AW11: =AM11 -> 0 | AX11: =SUM(AP11:AW11) -> 5681.8267 | AY11: =IF(L2>=1,AX11/$A$5,0) -> 0 | AZ11: ='Cobre Ácido'!V15 -> 16768.63 | BA11: ='Resumo M.O'!$H$14 -> 1490.6153 | BB11: ='Resumo M.O'!$H$29 -> 2265.2114 | BC11: ='Resumo Custos Variáveis'!$J$21 -> 0 | BD11: ='Outros Custos'!$H$31 -> 0 | BE11: =Transporte!$H$20 -> 0 | BF11: =Manutenção!$H$21 -> 3061.5385 | BG11: =AW11 -> 0 | BH11: =SUM(AZ11:BG11) -> 23585.995 | BI11: =IF(L2>=1,BH11/$A$5,0) -> 0 | BJ11: ='Cobre Ácido'!Y15 -> 0 | BK11: ='Resumo M.O'!$I$14 -> 1490.6153 | BL11: ='Resumo M.O'!$I$29 -> 2265.2114 | BM11: ='Resumo Custos Variáveis'!$K$21 -> 0 | BN11: ='Outros Custos'!$I$31 -> 0 | BO11: =Transporte!$I$20 -> 0 | BP11: =Manutenção!$I$21 -> 3030.7692 | BQ11: =BG11 -> 0 | BR11: =SUM(BJ11:BQ11) -> 6786.5959 | BS11: =IF(L2>=1,BR11/$A$5,0) -> 0 | BT11: ='Cobre Ácido'!AB15 -> 0 | BU11: ='Resumo M.O'!$J$14 -> 1490.6153 | BV11: ='Resumo M.O'!$J$29 -> 2265.2114 | BW11: ='Resumo Custos Variáveis'!$L$21 -> 0 | BX11: ='Outros Custos'!$J$31 -> 0 | BY11: =Transporte!$J$20 -> 0 | BZ11: =Manutenção!$J$21 -> 0 | CA11: =BQ11 -> 0 | CB11: =SUM(BT11:CA11) -> 3755.8267 | CC11: =IF(L2>=1,CB11/$A$5,0) -> 0 | CD11: ='Cobre Ácido'!AE15 -> 0 | CE11: ='Resumo M.O'!$K$14 -> 1490.6153 | CF11: ='Resumo M.O'!$K$29 -> 2265.2114 | CG11: ='Resumo Custos Variáveis'!$M$21 -> 0 | CH11: ='Outros Custos'!$K$31 -> 0 | CI11: =Transporte!$K$20 -> 0 | CJ11: =Manutenção!$K$21 -> 0 | CK11: =CA11 -> 0 | CL11: =SUM(CD11:CK11) -> 3755.8267 | CM11: =IF(L2>=1,CL11/$A$5,0) -> 0 | CN11: ='Cobre Ácido'!AH15 -> 0 | CO11: ='Resumo M.O'!$L$14 -> 1490.6153 | CP11: ='Resumo M.O'!$L$29 -> 2265.2114 | CQ11: ='Resumo Custos Variáveis'!$N$21 -> 0 | CR11: ='Outros Custos'!$L$31 -> 0 | CS11: =Transporte!$L$20 -> 0 | CT11: =Manutenção!$L$21 -> 0 | CU11: =CK11 -> 0 | CV11: =SUM(CN11:CU11) -> 3755.8267 | CW11: =IF(L2>=1,CV11/$A$5,0) -> 0 | CX11: ='Cobre Ácido'!AK15 -> 0 | CY11: ='Resumo M.O'!$M$14 -> 1490.6153 | CZ11: ='Resumo M.O'!$M$29 -> 2265.2114 | DA11: ='Resumo Custos Variáveis'!$O$21 -> 0 | DB11: ='Outros Custos'!$M$31 -> 0 | DC11: =Transporte!$M$20 -> 0 | DD11: =Manutenção!$M$21 -> 0 | DE11: =CU11 -> 0 | DF11: =SUM(CX11:DE11) -> 3755.8267 | DG11: =IF(L2>=1,DF11/$A$5,0) -> 0 | DH11: ='Cobre Ácido'!AN15 -> 0 | DI11: ='Resumo M.O'!$N$14 -> 1490.6153 | DJ11: ='Resumo M.O'!$N$29 -> 2265.2114 | DK11: ='Resumo Custos Variáveis'!$P$21 -> 0 | DL11: ='Outros Custos'!$N$31 -> 0 | DM11: =Transporte!$N$20 -> 0 | DN11: =Manutenção!$N$21 -> 0 | DO11: =DE11 -> 0 | DP11: =SUM(DH11:DO11) -> 3755.8267 | DQ11: =IF(L2>=1,DP11/$A$5,0) -> 0 | DS11: =K11 -> 0 | DT11: =U11 -> 0 | DU11: =AE11 -> 0 | DV11: =AO11 -> 0 | DW11: =AY11 -> 0 | DX11: =BI11 -> 0 | DY11: =BS11 -> 0 | DZ11: =CC11 -> 0 | EA11: =CM11 -> 0 | EB11: =CW11 -> 0 | EC11: =DG11 -> 0 | ED11: =DQ11 -> 0 | EF11: =B11/$A$5 -> 0 | EG11: =L11/$A$5 -> 0 | EH11: =V11/$A$5 -> 116.948 | EI11: =AF11/$A$5 -> 103.44436 | EJ11: =AP11/$A$5 -> 8.7545455 | EK11: =AZ11/$A$5 -> 76.221045 | EL11: =BJ11/$A$5 -> 0 | EM11: =BT11/$A$5 -> 0 | EN11: =CD11/$A$5 -> 0 | EO11: =CN11/$A$5 -> 0 | EP11: =CX11/$A$5 -> 0 | EQ11: =DH11/$A$5 -> 0
A12: Desengraxante Quí | B12: ='Desengraxante Quí'!G15 -> 0 | C12: ='Resumo M.O'!$C$14 -> 1490.6153 | D12: ='Resumo M.O'!$C$29 -> 2265.2114 | E12: ='Resumo Custos Variáveis'!$E$21 -> 0 | F12: ='Outros Custos'!$C$31 -> 0 | G12: =Transporte!$C$20 -> 0 | H12: =Manutenção!$C$21 -> 0 | I12: =Investimentos!G28 -> 0 | J12: =SUM(B12:I12) -> 3755.8267 | K12: =IF($L$2>=1,J12/$A$5,0) -> 0 | L12: ='Desengraxante Quí'!J15 -> 0 | M12: ='Resumo M.O'!$D$14 -> 1490.6153 | N12: ='Resumo M.O'!$D$29 -> 2265.2114 | O12: ='Resumo Custos Variáveis'!$F$21 -> 0 | P12: ='Outros Custos'!$D$31 -> 0 | Q12: =Transporte!$D$20 -> 0 | R12: =Manutenção!$D$21 -> 0 | S12: =I12 -> 0 | T12: =SUM(L12:S12) -> 3755.8267 | U12: =IF($L$2>=1,T12/$A$5,0) -> 0 | V12: ='Desengraxante Quí'!M15 -> 58.05 | W12: ='Resumo M.O'!$E$14 -> 1490.6153 | X12: ='Resumo M.O'!$E$29 -> 2265.2114 | Y12: ='Resumo Custos Variáveis'!$G$21 -> 2404.5263 | Z12: ='Outros Custos'!$E$31 -> 0 | AA12: =Transporte!$E$20 -> 0 | AB12: =Manutenção!$E$21 -> 0 | AC12: =S12 -> 0 | AD12: =SUM(V12:AC12) -> 6218.403 | AE12: =IF($L$2>=1,AD12/$A$5,0) -> 0 | AF12: ='Desengraxante Quí'!P15 -> 11.61 | AG12: ='Resumo M.O'!$F$14 -> 1490.6153 | AH12: ='Resumo M.O'!$F$29 -> 2265.2114 | AI12: ='Resumo Custos Variáveis'!$H$21 -> 1573.8421 | AJ12: ='Outros Custos'!$F$31 -> 0 | AK12: =Transporte!$F$20 -> 0 | AL12: =Manutenção!$F$21 -> 0 | AM12: =AC12 -> 0 | AN12: =SUM(AF12:AM12) -> 5341.2788 | AO12: =IF(L2>=1,AN12/$A$5,0) -> 0 | AP12: ='Desengraxante Quí'!S15 -> 0 | AQ12: ='Resumo M.O'!$G$14 -> 1490.6153 | AR12: ='Resumo M.O'!$G$29 -> 2265.2114 | AS12: ='Resumo Custos Variáveis'!$I$21 -> 0 | AT12: ='Outros Custos'!$G$31 -> 0 | AU12: =Transporte!$G$20 -> 0 | AV12: =Manutenção!$G$21 -> 0 | AW12: =AM12 -> 0 | AX12: =SUM(AP12:AW12) -> 3755.8267 | AY12: =IF(L2>=1,AX12/$A$5,0) -> 0 | AZ12: ='Desengraxante Quí'!V15 -> 0 | BA12: ='Resumo M.O'!$H$14 -> 1490.6153 | BB12: ='Resumo M.O'!$H$29 -> 2265.2114 | BC12: ='Resumo Custos Variáveis'!$J$21 -> 0 | BD12: ='Outros Custos'!$H$31 -> 0 | BE12: =Transporte!$H$20 -> 0 | BF12: =Manutenção!$H$21 -> 3061.5385 | BG12: =AW12 -> 0 | BH12: =SUM(AZ12:BG12) -> 6817.3651 | BI12: =IF(L2>=1,BH12/$A$5,0) -> 0 | BJ12: ='Desengraxante Quí'!Y15 -> 0 | BK12: ='Resumo M.O'!$I$14 -> 1490.6153 | BL12: ='Resumo M.O'!$I$29 -> 2265.2114 | BM12: ='Resumo Custos Variáveis'!$K$21 -> 0 | BN12: ='Outros Custos'!$I$31 -> 0 | BO12: =Transporte!$I$20 -> 0 | BP12: =Manutenção!$I$21 -> 3030.7692 | BQ12: =BG12 -> 0 | BR12: =SUM(BJ12:BQ12) -> 6786.5959 | BS12: =IF(L2>=1,BR12/$A$5,0) -> 0 | BT12: ='Desengraxante Quí'!AB15 -> 0 | BU12: ='Resumo M.O'!$J$14 -> 1490.6153 | BV12: ='Resumo M.O'!$J$29 -> 2265.2114 | BW12: ='Resumo Custos Variáveis'!$L$21 -> 0 | BX12: ='Outros Custos'!$J$31 -> 0 | BY12: =Transporte!$J$20 -> 0 | BZ12: =Manutenção!$J$21 -> 0 | CA12: =BQ12 -> 0 | CB12: =SUM(BT12:CA12) -> 3755.8267 | CC12: =IF(L2>=1,CB12/$A$5,0) -> 0 | CD12: ='Desengraxante Quí'!AE15 -> 0 | CE12: ='Resumo M.O'!$K$14 -> 1490.6153 | CF12: ='Resumo M.O'!$K$29 -> 2265.2114 | CG12: ='Resumo Custos Variáveis'!$M$21 -> 0 | CH12: ='Outros Custos'!$K$31 -> 0 | CI12: =Transporte!$K$20 -> 0 | CJ12: =Manutenção!$K$21 -> 0 | CK12: =CA12 -> 0 | CL12: =SUM(CD12:CK12) -> 3755.8267 | CM12: =IF(L2>=1,CL12/$A$5,0) -> 0 | CN12: ='Desengraxante Quí'!AH15 -> 0 | CO12: ='Resumo M.O'!$L$14 -> 1490.6153 | CP12: ='Resumo M.O'!$L$29 -> 2265.2114 | CQ12: ='Resumo Custos Variáveis'!$N$21 -> 0 | CR12: ='Outros Custos'!$L$31 -> 0 | CS12: =Transporte!$L$20 -> 0 | CT12: =Manutenção!$L$21 -> 0 | CU12: =CK12 -> 0 | CV12: =SUM(CN12:CU12) -> 3755.8267 | CW12: =IF(L2>=1,CV12/$A$5,0) -> 0 | CX12: ='Desengraxante Quí'!AK15 -> 0 | CY12: ='Resumo M.O'!$M$14 -> 1490.6153 | CZ12: ='Resumo M.O'!$M$29 -> 2265.2114 | DA12: ='Resumo Custos Variáveis'!$O$21 -> 0 | DB12: ='Outros Custos'!$M$31 -> 0 | DC12: =Transporte!$M$20 -> 0 | DD12: =Manutenção!$M$21 -> 0 | DE12: =CU12 -> 0 | DF12: =SUM(CX12:DE12) -> 3755.8267 | DG12: =IF(L2>=1,DF12/$A$5,0) -> 0 | DH12: ='Desengraxante Quí'!AN15 -> 0 | DI12: ='Resumo M.O'!$N$14 -> 1490.6153 | DJ12: ='Resumo M.O'!$N$29 -> 2265.2114 | DK12: ='Resumo Custos Variáveis'!$P$21 -> 0 | DL12: ='Outros Custos'!$N$31 -> 0 | DM12: =Transporte!$N$20 -> 0 | DN12: =Manutenção!$N$21 -> 0 | DO12: =DE12 -> 0 | DP12: =SUM(DH12:DO12) -> 3755.8267 | DQ12: =IF(L2>=1,DP12/$A$5,0) -> 0 | DS12: =K12 -> 0 | DT12: =U12 -> 0 | DU12: =AE12 -> 0 | DV12: =AO12 -> 0 | DW12: =AY12 -> 0 | DX12: =BI12 -> 0 | DY12: =BS12 -> 0 | DZ12: =CC12 -> 0 | EA12: =CM12 -> 0 | EB12: =CW12 -> 0 | EC12: =DG12 -> 0 | ED12: =DQ12 -> 0 | EF12: =B12/$A$5 -> 0 | EG12: =L12/$A$5 -> 0 | EH12: =V12/$A$5 -> 0.26386364 | EI12: =AF12/$A$5 -> 0.052772727 | EJ12: =AP12/$A$5 -> 0 | EK12: =AZ12/$A$5 -> 0 | EL12: =BJ12/$A$5 -> 0 | EM12: =BT12/$A$5 -> 0 | EN12: =CD12/$A$5 -> 0 | EO12: =CN12/$A$5 -> 0 | EP12: =CX12/$A$5 -> 0 | EQ12: =DH12/$A$5 -> 0
A13: Níquel Brilhante | B13: ='Níquel Brilhante'!G15 -> 0 | C13: ='Resumo M.O'!$C$14 -> 1490.6153 | D13: ='Resumo M.O'!$C$29 -> 2265.2114 | E13: ='Resumo Custos Variáveis'!$E$21 -> 0 | F13: ='Outros Custos'!$C$31 -> 0 | G13: =Transporte!$C$20 -> 0 | H13: =Manutenção!$C$21 -> 0 | I13: =Investimentos!G32 -> 0 | J13: =SUM(B13:I13) -> 3755.8267 | K13: =IF($L$2>=1,J13/$A$5,0) -> 0 | L13: ='Níquel Brilhante'!J15 -> 0 | M13: ='Resumo M.O'!$D$14 -> 1490.6153 | N13: ='Resumo M.O'!$D$29 -> 2265.2114 | O13: ='Resumo Custos Variáveis'!$F$21 -> 0 | P13: ='Outros Custos'!$D$31 -> 0 | Q13: =Transporte!$D$20 -> 0 | R13: =Manutenção!$D$21 -> 0 | S13: =I13 -> 0 | T13: =SUM(L13:S13) -> 3755.8267 | U13: =IF($L$2>=1,T13/$A$5,0) -> 0 | V13: ='Níquel Brilhante'!M15 -> 37847.69 | W13: ='Resumo M.O'!$E$14 -> 1490.6153 | X13: ='Resumo M.O'!$E$29 -> 2265.2114 | Y13: ='Resumo Custos Variáveis'!$G$21 -> 2404.5263 | Z13: ='Outros Custos'!$E$31 -> 0 | AA13: =Transporte!$E$20 -> 0 | AB13: =Manutenção!$E$21 -> 0 | AC13: =S13 -> 0 | AD13: =SUM(V13:AC13) -> 44008.043 | AE13: =IF($L$2>=1,AD13/$A$5,0) -> 0 | AF13: ='Níquel Brilhante'!P15 -> 30695.13 | AG13: ='Resumo M.O'!$F$14 -> 1490.6153 | AH13: ='Resumo M.O'!$F$29 -> 2265.2114 | AI13: ='Resumo Custos Variáveis'!$H$21 -> 1573.8421 | AJ13: ='Outros Custos'!$F$31 -> 0 | AK13: =Transporte!$F$20 -> 0 | AL13: =Manutenção!$F$21 -> 0 | AM13: =AC13 -> 0 | AN13: =SUM(AF13:AM13) -> 36024.799 | AO13: =IF(L2>=1,(AN13/$A$5)/2,0) -> 0 | AP13: ='Níquel Brilhante'!S15 -> 171.54 | AQ13: ='Resumo M.O'!$G$14 -> 1490.6153 | AR13: ='Resumo M.O'!$G$29 -> 2265.2114 | AS13: ='Resumo Custos Variáveis'!$I$21 -> 0 | AT13: ='Outros Custos'!$G$31 -> 0 | AU13: =Transporte!$G$20 -> 0 | AV13: =Manutenção!$G$21 -> 0 | AW13: =AM13 -> 0 | AX13: =SUM(AP13:AW13) -> 3927.3667 | AY13: =IF(L2>=1,(AX13/$A$5)/2,0) -> 0 | AZ13: ='Níquel Brilhante'!V15 -> 121.68 | BA13: ='Resumo M.O'!$H$14 -> 1490.6153 | BB13: ='Resumo M.O'!$H$29 -> 2265.2114 | BC13: ='Resumo Custos Variáveis'!$J$21 -> 0 | BD13: ='Outros Custos'!$H$31 -> 0 | BE13: =Transporte!$H$20 -> 0 | BF13: =Manutenção!$H$21 -> 3061.5385 | BG13: =AW13 -> 0 | BH13: =SUM(AZ13:BG13) -> 6939.0451 | BI13: =IF(L2>=1,(BH13/$A$5)/2,0) -> 0 | BJ13: ='Níquel Brilhante'!Y15 -> 0 | BK13: ='Resumo M.O'!$I$14 -> 1490.6153 | BL13: ='Resumo M.O'!$I$29 -> 2265.2114 | BM13: ='Resumo Custos Variáveis'!$K$21 -> 0 | BN13: ='Outros Custos'!$I$31 -> 0 | BO13: =Transporte!$I$20 -> 0 | BP13: =Manutenção!$I$21 -> 3030.7692 | BQ13: =BG13 -> 0 | BR13: =SUM(BJ13:BQ13) -> 6786.5959 | BS13: =IF(L2>=1,(BR13/$A$5)/2,0) -> 0 | BT13: ='Níquel Brilhante'!AB15 -> 0 | BU13: ='Resumo M.O'!$J$14 -> 1490.6153 | BV13: ='Resumo M.O'!$J$29 -> 2265.2114 | BW13: ='Resumo Custos Variáveis'!$L$21 -> 0 | BX13: ='Outros Custos'!$J$31 -> 0 | BY13: =Transporte!$J$20 -> 0 | BZ13: =Manutenção!$J$21 -> 0 | CA13: =BQ13 -> 0 | CB13: =SUM(BT13:CA13) -> 3755.8267 | CC13: =IF(L2>=1,(CB13/$A$5)/2,0) -> 0 | CD13: ='Níquel Brilhante'!AE15 -> 0 | CE13: ='Resumo M.O'!$K$14 -> 1490.6153 | CF13: ='Resumo M.O'!$K$29 -> 2265.2114 | CG13: ='Resumo Custos Variáveis'!$M$21 -> 0 | CH13: ='Outros Custos'!$K$31 -> 0 | CI13: =Transporte!$K$20 -> 0 | CJ13: =Manutenção!$K$21 -> 0 | CK13: =CA13 -> 0 | CL13: =SUM(CD13:CK13) -> 3755.8267 | CM13: =IF(L2>=1,(CL13/$A$5)/2,0) -> 0 | CN13: ='Níquel Brilhante'!AH15 -> 0 | CO13: ='Resumo M.O'!$L$14 -> 1490.6153 | CP13: ='Resumo M.O'!$L$29 -> 2265.2114 | CQ13: ='Resumo Custos Variáveis'!$N$21 -> 0 | CR13: ='Outros Custos'!$L$31 -> 0 | CS13: =Transporte!$L$20 -> 0 | CT13: =Manutenção!$L$21 -> 0 | CU13: =CK13 -> 0 | CV13: =SUM(CN13:CU13) -> 3755.8267 | CW13: =IF(L2>=1,(CV13/$A$5)/2,0) -> 0 | CX13: ='Níquel Brilhante'!AK15 -> 0 | CY13: ='Resumo M.O'!$M$14 -> 1490.6153 | CZ13: ='Resumo M.O'!$M$29 -> 2265.2114 | DA13: ='Resumo Custos Variáveis'!$O$21 -> 0 | DB13: ='Outros Custos'!$M$31 -> 0 | DC13: =Transporte!$M$20 -> 0 | DD13: =Manutenção!$M$21 -> 0 | DE13: =CU13 -> 0 | DF13: =SUM(CX13:DE13) -> 3755.8267 | DG13: =IF(L2>=1,(DF13/$A$5)/2,0) -> 0 | DH13: ='Níquel Brilhante'!AN15 -> 0 | DI13: ='Resumo M.O'!$N$14 -> 1490.6153 | DJ13: ='Resumo M.O'!$N$29 -> 2265.2114 | DK13: ='Resumo Custos Variáveis'!$P$21 -> 0 | DL13: ='Outros Custos'!$N$31 -> 0 | DM13: =Transporte!$N$20 -> 0 | DN13: =Manutenção!$N$21 -> 0 | DO13: =DE13 -> 0 | DP13: =SUM(DH13:DO13) -> 3755.8267 | DQ13: =IF(L2>=1,(DP13/$A$5)/2,0) -> 0 | DS13: =K13 -> 0 | DT13: =U13 -> 0 | DU13: =AE13 -> 0 | DV13: =AO13 -> 0 | DW13: =AY13 -> 0 | DX13: =BI13 -> 0 | DY13: =BS13 -> 0 | DZ13: =CC13 -> 0 | EA13: =CM13 -> 0 | EB13: =CW13 -> 0 | EC13: =DG13 -> 0 | ED13: =DQ13 -> 0 | EF13: =(B13/$A$5) -> 0 | EG13: =L13/$A$5 -> 0 | EH13: =V13/$A$5 -> 172.03495 | EI13: =AF13/$A$5 -> 139.52332 | EJ13: =AP13/$A$5 -> 0.77972727 | EK13: =AZ13/$A$5 -> 0.55309091 | EL13: =BJ13/$A$5 -> 0 | EM13: =BT13/$A$5 -> 0 | EN13: =CD13/$A$5 -> 0 | EO13: =CN13/$A$5 -> 0 | EP13: =CX13/$A$5 -> 0 | EQ13: =DH13/$A$5 -> 0
A14: Níquel Strik (2) | B14: ='Níquel Strik (2)'!G14 -> 0 | C14: ='Resumo M.O'!$C$14 -> 1490.6153 | D14: ='Resumo M.O'!$C$29 -> 2265.2114 | E14: ='Resumo Custos Variáveis'!$E$21 -> 0 | F14: ='Outros Custos'!$C$31 -> 0 | G14: =Transporte!$C$20 -> 0 | H14: =Manutenção!$C$21 -> 0 | I14: =Investimentos!G36 -> 0 | J14: =SUM(B14:I14) -> 3755.8267 | K14: =IF($L$2>=1,J14/$A$5,0) -> 0 | L14: ='Níquel Strik (2)'!J14 -> 0 | M14: ='Resumo M.O'!$D$14 -> 1490.6153 | N14: ='Resumo M.O'!$D$29 -> 2265.2114 | O14: ='Resumo Custos Variáveis'!$F$21 -> 0 | P14: ='Outros Custos'!$D$31 -> 0 | Q14: =Transporte!$D$20 -> 0 | R14: =Manutenção!$D$21 -> 0 | S14: =I14 -> 0 | T14: =SUM(L14:S14) -> 3755.8267 | U14: =IF($L$2>=1,T14/$A$5,0) -> 0 | V14: ='Níquel Strik (2)'!M14 -> 3135.25 | W14: ='Resumo M.O'!$E$14 -> 1490.6153 | X14: ='Resumo M.O'!$E$29 -> 2265.2114 | Y14: ='Resumo Custos Variáveis'!$G$21 -> 2404.5263 | Z14: ='Outros Custos'!$E$31 -> 0 | AA14: =Transporte!$E$20 -> 0 | AB14: =Manutenção!$E$21 -> 0 | AC14: =S14 -> 0 | AD14: =SUM(V14:AC14) -> 9295.603 | AE14: =IF($L$2>=1,AD14/$A$5,0) -> 0 | AF14: ='Níquel Strik (2)'!P14 -> 6041.56 | AG14: ='Resumo M.O'!$F$14 -> 1490.6153 | AH14: ='Resumo M.O'!$F$29 -> 2265.2114 | AI14: ='Resumo Custos Variáveis'!$H$21 -> 1573.8421 | AJ14: ='Outros Custos'!$F$31 -> 0 | AK14: =Transporte!$F$20 -> 0 | AL14: =Manutenção!$F$21 -> 0 | AM14: =AC14 -> 0 | AN14: =SUM(AF14:AM14) -> 11371.229 | AO14: =IF(L2>=1,(AN14/$A$5)/2,0) -> 0 | AP14: ='Níquel Strik (2)'!S14 -> 11919.6 | AQ14: ='Resumo M.O'!$G$14 -> 1490.6153 | AR14: ='Resumo M.O'!$G$29 -> 2265.2114 | AS14: ='Resumo Custos Variáveis'!$I$21 -> 0 | AT14: ='Outros Custos'!$G$31 -> 0 | AU14: =Transporte!$G$20 -> 0 | AV14: =Manutenção!$G$21 -> 0 | AW14: =AM14 -> 0 | AX14: =SUM(AP14:AW14) -> 15675.427 | AY14: =IF(L2>=1,(AX14/$A$5)/2,0) -> 0 | AZ14: ='Níquel Strik (2)'!V14 -> 0 | BA14: ='Resumo M.O'!$H$14 -> 1490.6153 | BB14: ='Resumo M.O'!$H$29 -> 2265.2114 | BC14: ='Resumo Custos Variáveis'!$J$21 -> 0 | BD14: ='Outros Custos'!$H$31 -> 0 | BE14: =Transporte!$H$20 -> 0 | BF14: =Manutenção!$H$21 -> 3061.5385 | BG14: =AW14 -> 0 | BH14: =SUM(AZ14:BG14) -> 6817.3651 | BI14: =IF(L2>=1,(BH14/$A$5)/2,0) -> 0 | BJ14: ='Níquel Strik (2)'!Y14 -> 0 | BK14: ='Resumo M.O'!$I$14 -> 1490.6153 | BL14: ='Resumo M.O'!$I$29 -> 2265.2114 | BM14: ='Resumo Custos Variáveis'!$K$21 -> 0 | BN14: ='Outros Custos'!$I$31 -> 0 | BO14: =Transporte!$I$20 -> 0 | BP14: =Manutenção!$I$21 -> 3030.7692 | BQ14: =BG14 -> 0 | BR14: =SUM(BJ14:BQ14) -> 6786.5959 | BS14: =IF(L2>=1,(BR14/$A$5),0) -> 0 | BT14: ='Níquel Strik (2)'!AB14 -> 0 | BU14: ='Resumo M.O'!$J$14 -> 1490.6153 | BV14: ='Resumo M.O'!$J$29 -> 2265.2114 | BW14: ='Resumo Custos Variáveis'!$L$21 -> 0 | BX14: ='Outros Custos'!$J$31 -> 0 | BY14: =Transporte!$J$20 -> 0 | BZ14: =Manutenção!$J$21 -> 0 | CA14: =BQ14 -> 0 | CB14: =SUM(BT14:CA14) -> 3755.8267 | CC14: =IF(L2>=1,(CB14/$A$5)/2,0) -> 0 | CD14: ='Níquel Strik (2)'!AE14 -> 0 | CE14: ='Resumo M.O'!$K$14 -> 1490.6153 | CF14: ='Resumo M.O'!$K$29 -> 2265.2114 | CG14: ='Resumo Custos Variáveis'!$M$21 -> 0 | CH14: ='Outros Custos'!$K$31 -> 0 | CI14: =Transporte!$K$20 -> 0 | CJ14: =Manutenção!$K$21 -> 0 | CK14: =CA14 -> 0 | CL14: =SUM(CD14:CK14) -> 3755.8267 | CM14: =IF(L2>=1,(CL14/$A$5)/2,0) -> 0 | CN14: ='Níquel Strik (2)'!AH14 -> 0 | CO14: ='Resumo M.O'!$L$14 -> 1490.6153 | CP14: ='Resumo M.O'!$L$29 -> 2265.2114 | CQ14: ='Resumo Custos Variáveis'!$N$21 -> 0 | CR14: ='Outros Custos'!$L$31 -> 0 | CS14: =Transporte!$L$20 -> 0 | CT14: =Manutenção!$L$21 -> 0 | CU14: =CK14 -> 0 | CV14: =SUM(CN14:CU14) -> 3755.8267 | CW14: =IF(L2>=1,(CV14/$A$5)/2,0) -> 0 | CX14: ='Níquel Strik (2)'!AK14 -> 0 | CY14: ='Resumo M.O'!$M$14 -> 1490.6153 | CZ14: ='Resumo M.O'!$M$29 -> 2265.2114 | DA14: ='Resumo Custos Variáveis'!$O$21 -> 0 | DB14: ='Outros Custos'!$M$31 -> 0 | DC14: =Transporte!$M$20 -> 0 | DD14: =Manutenção!$M$21 -> 0 | DE14: =CU14 -> 0 | DF14: =SUM(CX14:DE14) -> 3755.8267 | DG14: =IF(L2>=1,(DF14/$A$5)/2,0) -> 0 | DH14: ='Níquel Strik (2)'!AN14 -> 0 | DI14: ='Resumo M.O'!$N$14 -> 1490.6153 | DJ14: ='Resumo M.O'!$N$29 -> 2265.2114 | DK14: ='Resumo Custos Variáveis'!$P$21 -> 0 | DL14: ='Outros Custos'!$N$31 -> 0 | DM14: =Transporte!$N$20 -> 0 | DN14: =Manutenção!$N$21 -> 0 | DO14: =DE14 -> 0 | DP14: =SUM(DH14:DO14) -> 3755.8267 | DQ14: =IF(L2>=1,(DP14/$A$5)/2,0) -> 0 | DS14: =K14 -> 0 | DT14: =U14 -> 0 | DU14: =AE14 -> 0 | DV14: =AO14 -> 0 | DW14: =AY14 -> 0 | DX14: =BI14 -> 0 | DY14: =BS14 -> 0 | DZ14: =CC14 -> 0 | EA14: =CM14 -> 0 | EB14: =CW14 -> 0 | EC14: =DG14 -> 0 | ED14: =DQ14 -> 0 | EF14: =(B14/$A$5) -> 0 | EG14: =L14/$A$5 -> 0 | EH14: =V14/$A$5 -> 14.251136 | EI14: =AF14/$A$5 -> 27.461636 | EJ14: =AP14/$A$5 -> 54.18 | EK14: =AZ14/$A$5 -> 0 | EL14: =BJ14/$A$5 -> 0 | EM14: =BT14/$A$5 -> 0 | EN14: =CD14/$A$5 -> 0 | EO14: =CN14/$A$5 -> 0 | EP14: =CX14/$A$5 -> 0 | EQ14: =DH14/$A$5 -> 0
A15: Cromo | B15: =Cromo!G14 -> 0 | C15: ='Resumo M.O'!$C$14 -> 1490.6153 | D15: ='Resumo M.O'!$C$29 -> 2265.2114 | E15: ='Resumo Custos Variáveis'!$E$21 -> 0 | F15: ='Outros Custos'!$C$31 -> 0 | G15: =Transporte!$C$20 -> 0 | H15: =Manutenção!$C$21 -> 0 | I15: =Investimentos!G40 -> 0 | J15: =SUM(B15:I15) -> 3755.8267 | K15: =IF($L$2>=1,J15/$A$5,0) -> 0 | L15: =Cromo!J14 -> 0 | M15: ='Resumo M.O'!$D$14 -> 1490.6153 | N15: ='Resumo M.O'!$D$29 -> 2265.2114 | O15: ='Resumo Custos Variáveis'!$F$21 -> 0 | P15: ='Outros Custos'!$D$31 -> 0 | Q15: =Transporte!$D$20 -> 0 | R15: =Manutenção!$D$21 -> 0 | S15: =I15 -> 0 | T15: =SUM(L15:S15) -> 3755.8267 | U15: =IF($L$2>=1,T15/$A$5,0) -> 0 | V15: =Cromo!M14 -> 29778.51 | W15: ='Resumo M.O'!$E$14 -> 1490.6153 | X15: ='Resumo M.O'!$E$29 -> 2265.2114 | Y15: ='Resumo Custos Variáveis'!$G$21 -> 2404.5263 | Z15: ='Outros Custos'!$E$31 -> 0 | AA15: =Transporte!$E$20 -> 0 | AB15: =Manutenção!$E$21 -> 0 | AC15: =S15 -> 0 | AD15: =SUM(V15:AC15) -> 35938.863 | AE15: =IF($L$2>=1,AD15/$A$5,0) -> 0 | AF15: =Cromo!P14 -> 29439.66 | AG15: ='Resumo M.O'!$F$14 -> 1490.6153 | AH15: ='Resumo M.O'!$F$29 -> 2265.2114 | AI15: ='Resumo Custos Variáveis'!$H$21 -> 1573.8421 | AJ15: ='Outros Custos'!$F$31 -> 0 | AK15: =Transporte!$F$20 -> 0 | AL15: =Manutenção!$F$21 -> 0 | AM15: =AC15 -> 0 | AN15: =SUM(AF15:AM15) -> 34769.329 | AO15: =IF(L2>=1,(AN15/$A$5)/2,0) -> 0 | AP15: =Cromo!S14 -> 24196.5 | AQ15: ='Resumo M.O'!$G$14 -> 1490.6153 | AR15: ='Resumo M.O'!$G$29 -> 2265.2114 | AS15: ='Resumo Custos Variáveis'!$I$21 -> 0 | AT15: ='Outros Custos'!$G$31 -> 0 | AU15: =Transporte!$G$20 -> 0 | AV15: =Manutenção!$G$21 -> 0 | AW15: =AM15 -> 0 | AX15: =SUM(AP15:AW15) -> 27952.327 | AY15: =IF($L$2>=1,(AX15/$A$5)/2,0) -> 0 | AZ15: =Cromo!V14 -> 24196.5 | BA15: ='Resumo M.O'!$H$14 -> 1490.6153 | BB15: ='Resumo M.O'!$H$29 -> 2265.2114 | BC15: ='Resumo Custos Variáveis'!$J$21 -> 0 | BD15: ='Outros Custos'!$H$31 -> 0 | BE15: =Transporte!$H$20 -> 0 | BF15: =Manutenção!$H$21 -> 3061.5385 | BG15: =AW15 -> 0 | BH15: =SUM(AZ15:BG15) -> 31013.865 | BI15: =IF($L$2>=1,(BH15/$A$5)/2,0) -> 0 | BJ15: =Cromo!Y14 -> 0 | BK15: ='Resumo M.O'!$I$14 -> 1490.6153 | BL15: ='Resumo M.O'!$I$29 -> 2265.2114 | BM15: ='Resumo Custos Variáveis'!$K$21 -> 0 | BN15: ='Outros Custos'!$I$31 -> 0 | BO15: =Transporte!$I$20 -> 0 | BP15: =Manutenção!$I$21 -> 3030.7692 | BQ15: =BG15 -> 0 | BR15: =SUM(BJ15:BQ15) -> 6786.5959 | BS15: =IF($L$2>=1,(BR15/$A$5),0) -> 0 | BT15: =Cromo!AB14 -> 0 | BU15: ='Resumo M.O'!$J$14 -> 1490.6153 | BV15: ='Resumo M.O'!$J$29 -> 2265.2114 | BW15: ='Resumo Custos Variáveis'!$L$21 -> 0 | BX15: ='Outros Custos'!$J$31 -> 0 | BY15: =Transporte!$J$20 -> 0 | BZ15: =Manutenção!$J$21 -> 0 | CA15: =BQ15 -> 0 | CB15: =SUM(BT15:CA15) -> 3755.8267 | CC15: =IF($L$2>=1,(CB15/$A$5)/2,0) -> 0 | CD15: =Cromo!AE14 -> 0 | CE15: ='Resumo M.O'!$K$14 -> 1490.6153 | CF15: ='Resumo M.O'!$K$29 -> 2265.2114 | CG15: ='Resumo Custos Variáveis'!$M$21 -> 0 | CH15: ='Outros Custos'!$K$31 -> 0 | CI15: =Transporte!$K$20 -> 0 | CJ15: =Manutenção!$K$21 -> 0 | CK15: =CA15 -> 0 | CL15: =SUM(CD15:CK15) -> 3755.8267 | CM15: =IF($L$2>=1,(CL15/$A$5)/2,0) -> 0 | CN15: =Cromo!AH14 -> 0 | CO15: ='Resumo M.O'!$L$14 -> 1490.6153 | CP15: ='Resumo M.O'!$L$29 -> 2265.2114 | CQ15: ='Resumo Custos Variáveis'!$N$21 -> 0 | CR15: ='Outros Custos'!$L$31 -> 0 | CS15: =Transporte!$L$20 -> 0 | CT15: =Manutenção!$L$21 -> 0 | CU15: =CK15 -> 0 | CV15: =SUM(CN15:CU15) -> 3755.8267 | CW15: =IF($L$2>=1,(CV15/$A$5)/2,0) -> 0 | CX15: =Cromo!AK14 -> 0 | CY15: ='Resumo M.O'!$M$14 -> 1490.6153 | CZ15: ='Resumo M.O'!$M$29 -> 2265.2114 | DA15: ='Resumo Custos Variáveis'!$O$21 -> 0 | DB15: ='Outros Custos'!$M$31 -> 0 | DC15: =Transporte!$M$20 -> 0 | DD15: =Manutenção!$M$21 -> 0 | DE15: =CU15 -> 0 | DF15: =SUM(CX15:DE15) -> 3755.8267 | DG15: =IF($L$2>=1,(DF15/$A$5)/2,0) -> 0 | DH15: =Cromo!AN14 -> 0 | DI15: ='Resumo M.O'!$N$14 -> 1490.6153 | DJ15: ='Resumo M.O'!$N$29 -> 2265.2114 | DK15: ='Resumo Custos Variáveis'!$P$21 -> 0 | DL15: ='Outros Custos'!$N$31 -> 0 | DM15: =Transporte!$N$20 -> 0 | DN15: =Manutenção!$N$21 -> 0 | DO15: =DE15 -> 0 | DP15: =SUM(DH15:DO15) -> 3755.8267 | DQ15: =IF(L2>=1,(DP15/$A$5)/2,0) -> 0 | DS15: =K15 -> 0 | DT15: =U15 -> 0 | DU15: =AE15 -> 0 | DV15: =AO15 -> 0 | DW15: =AY15 -> 0 | DX15: =BI15 -> 0 | DY15: =BS15 -> 0 | DZ15: =CC15 -> 0 | EA15: =CM15 -> 0 | EB15: =CW15 -> 0 | EC15: =DG15 -> 0 | ED15: =DQ15 -> 0 | EF15: =(B15/$A$5) -> 0 | EG15: =L15/$A$5 -> 0 | EH15: =V15/$A$5 -> 135.35686 | EI15: =AF15/$A$5 -> 133.81664 | EJ15: =AP15/$A$5 -> 109.98409 | EK15: =AZ15/$A$5 -> 109.98409 | EL15: =BJ15/$A$5 -> 0 | EM15: =BT15/$A$5 -> 0 | EN15: =CD15/$A$5 -> 0 | EO15: =CN15/$A$5 -> 0 | EP15: =CX15/$A$5 -> 0 | EQ15: =DH15/$A$5 -> 0
A16: Desplacante | B16: ='Desplacante '!G14 -> 0 | C16: ='Resumo M.O'!$C$14 -> 1490.6153 | D16: ='Resumo M.O'!$C$29 -> 2265.2114 | E16: ='Resumo Custos Variáveis'!$E$21 -> 0 | F16: ='Outros Custos'!$C$31 -> 0 | G16: =Transporte!$C$20 -> 0 | H16: =Manutenção!$C$21 -> 0 | I16: 0 | J16: =SUM(B16:I16) -> 3755.8267 | K16: =IF($L$2>=1,J16/$A$5,0) -> 0 | L16: ='Desplacante '!J14 -> 0 | M16: ='Resumo M.O'!$D$14 -> 1490.6153 | N16: ='Resumo M.O'!$D$29 -> 2265.2114 | O16: ='Resumo Custos Variáveis'!$F$21 -> 0 | P16: ='Outros Custos'!$D$31 -> 0 | Q16: =Transporte!$D$20 -> 0 | R16: =Manutenção!$D$21 -> 0 | S16: =I16 -> 0 | T16: =SUM(L16:S16) -> 3755.8267 | U16: =IF($L$2>=1,T16/$A$5,0) -> 0 | V16: ='Desplacante '!M14 -> 0 | W16: ='Resumo M.O'!$E$14 -> 1490.6153 | X16: ='Resumo M.O'!$E$29 -> 2265.2114 | Y16: ='Resumo Custos Variáveis'!$G$21 -> 2404.5263 | Z16: ='Outros Custos'!$E$31 -> 0 | AA16: =Transporte!$E$20 -> 0 | AB16: =Manutenção!$E$21 -> 0 | AC16: =S16 -> 0 | AD16: =SUM(V16:AC16) -> 6160.353 | AE16: =IF($L$2>=1,AD16/$A$5,0) -> 0 | AF16: ='Desplacante '!P14 -> 0 | AG16: ='Resumo M.O'!$F$14 -> 1490.6153 | AH16: ='Resumo M.O'!$F$29 -> 2265.2114 | AI16: ='Resumo Custos Variáveis'!$H$21 -> 1573.8421 | AJ16: ='Outros Custos'!$F$31 -> 0 | AK16: =Transporte!$F$20 -> 0 | AL16: =Manutenção!$F$21 -> 0 | AM16: =AC16 -> 0 | AN16: =SUM(AF16:AM16) -> 5329.6688 | AO16: =IF($L$2>=1,AN16/$A$5,0) -> 0 | AP16: ='Desplacante '!S14 -> 0 | AQ16: ='Resumo M.O'!$G$14 -> 1490.6153 | AR16: ='Resumo M.O'!$G$29 -> 2265.2114 | AS16: ='Resumo Custos Variáveis'!$I$21 -> 0 | AT16: ='Outros Custos'!$G$31 -> 0 | AU16: =Transporte!$G$20 -> 0 | AV16: =Manutenção!$G$21 -> 0 | AW16: =AM16 -> 0 | AX16: =SUM(AP16:AW16) -> 3755.8267 | AY16: =IF($L$2>=1,AX16/$A$5,0) -> 0 | AZ16: ='Desplacante '!V14 -> 0 | BA16: ='Resumo M.O'!$H$14 -> 1490.6153 | BB16: ='Resumo M.O'!$H$29 -> 2265.2114 | BC16: ='Resumo Custos Variáveis'!$J$21 -> 0 | BD16: ='Outros Custos'!$H$31 -> 0 | BE16: =Transporte!$H$20 -> 0 | BF16: =Manutenção!$H$21 -> 3061.5385 | BG16: =AW16 -> 0 | BH16: =SUM(AZ16:BG16) -> 6817.3651 | BI16: =IF($L$2>=1,BH16/$A$5,0) -> 0 | BJ16: ='Desplacante '!Y14 -> 0 | BK16: ='Resumo M.O'!$I$14 -> 1490.6153 | BL16: ='Resumo M.O'!$I$29 -> 2265.2114 | BM16: ='Resumo Custos Variáveis'!$K$21 -> 0 | BN16: ='Outros Custos'!$I$31 -> 0 | BO16: =Transporte!$I$20 -> 0 | BP16: =Manutenção!$I$21 -> 3030.7692 | BQ16: =BG16 -> 0 | BR16: =SUM(BJ16:BQ16) -> 6786.5959 | BS16: =IF($L$2>=1,BR16/$A$5,0) -> 0 | BT16: ='Desplacante '!AB14 -> 0 | BU16: ='Resumo M.O'!$J$14 -> 1490.6153 | BV16: ='Resumo M.O'!$J$29 -> 2265.2114 | BW16: ='Resumo Custos Variáveis'!$L$21 -> 0 | BX16: ='Outros Custos'!$J$31 -> 0 | BY16: =Transporte!$J$20 -> 0 | BZ16: =Manutenção!$J$21 -> 0 | CA16: =BQ16 -> 0 | CB16: =SUM(BT16:CA16) -> 3755.8267 | CC16: =IF($L$2>=1,CB16/$A$5,0) -> 0 | CD16: ='Desplacante '!AE14 -> 0 | CE16: ='Resumo M.O'!$K$14 -> 1490.6153 | CF16: ='Resumo M.O'!$K$29 -> 2265.2114 | CG16: ='Resumo Custos Variáveis'!$M$21 -> 0 | CH16: ='Outros Custos'!$K$31 -> 0 | CI16: =Transporte!$K$20 -> 0 | CJ16: =Manutenção!$K$21 -> 0 | CK16: =CA16 -> 0 | CL16: =SUM(CD16:CK16) -> 3755.8267 | CM16: =IF($L$2>=1,CL16/$A$5,0) -> 0 | CN16: ='Desplacante '!AH14 -> 0 | CO16: ='Resumo M.O'!$L$14 -> 1490.6153 | CP16: ='Resumo M.O'!$L$29 -> 2265.2114 | CQ16: ='Resumo Custos Variáveis'!$N$21 -> 0 | CR16: ='Outros Custos'!$L$31 -> 0 | CS16: =Transporte!$L$20 -> 0 | CT16: =Manutenção!$L$21 -> 0 | CU16: =CK16 -> 0 | CV16: =SUM(CN16:CU16) -> 3755.8267 | CW16: =IF($L$2>=1,CV16/$A$5,0) -> 0 | CX16: ='Desplacante '!AK14 -> 0 | CY16: ='Resumo M.O'!$M$14 -> 1490.6153 | CZ16: ='Resumo M.O'!$M$29 -> 2265.2114 | DA16: ='Resumo Custos Variáveis'!$O$21 -> 0 | DB16: ='Outros Custos'!$M$31 -> 0 | DC16: =Transporte!$M$20 -> 0 | DD16: =Manutenção!$M$21 -> 0 | DE16: =CU16 -> 0 | DF16: =SUM(CX16:DE16) -> 3755.8267 | DG16: =IF($L$2>=1,DF16/$A$5,0) -> 0 | DH16: ='Desplacante '!AN14 -> 0 | DI16: ='Resumo M.O'!$N$14 -> 1490.6153 | DJ16: ='Resumo M.O'!$N$29 -> 2265.2114 | DK16: ='Resumo Custos Variáveis'!$P$21 -> 0 | DL16: ='Outros Custos'!$N$31 -> 0 | DM16: =Transporte!$N$20 -> 0 | DN16: =Manutenção!$N$21 -> 0 | DO16: =DE16 -> 0 | DP16: =SUM(DH16:DO16) -> 3755.8267 | DQ16: =IF($L$2>=1,DP16/$A$5,0) -> 0 | DS16: =K16 -> 0 | DT16: =U16 -> 0 | DU16: =AE16 -> 0 | DV16: =AO16 -> 0 | DW16: =AY16 -> 0 | DX16: =BI16 -> 0 | DY16: =BS16 -> 0 | DZ16: =CC16 -> 0 | EA16: =CM16 -> 0 | EB16: =CW16 -> 0 | EC16: =DG16 -> 0 | ED16: =DQ16 -> 0 | EF16: =B16/$A$5 -> 0 | EG16: =L16/$A$5 -> 0 | EH16: =V16/$A$5 -> 0 | EI16: =AF16/$A$5 -> 0 | EJ16: =AP16/$A$5 -> 0 | EK16: =AZ16/$A$5 -> 0 | EL16: =BJ16/$A$5 -> 0 | EM16: =BT16/$A$5 -> 0 | EN16: =CD16/$A$5 -> 0 | EO16: =CN16/$A$5 -> 0 | EP16: =CX16/$A$5 -> 0 | EQ16: =DH16/$A$5 -> 0
A17: Pré Tratamento Verniz | B17: ='Pré Tratamento Verniz'!G14 -> 0 | C17: ='Resumo M.O'!$C$27 -> 1907.3422 | D17: ='Resumo M.O'!$C$31 -> 1526.3289 | E17: ='Resumo Custos Variáveis'!$E$21 -> 0 | F17: ='Outros Custos'!$C$31 -> 0 | G17: =Transporte!$C$20 -> 0 | H17: =Manutenção!$C$21 -> 0 | I17: 0 | J17: =SUM(B17:I17) -> 3433.6711 | K17: =IF($L$2>=1,J17/$A$5,0) -> 0 | L17: ='Pré Tratamento Verniz'!J14 -> 0 | M17: ='Resumo M.O'!$D$27 -> 1907.3422 | N17: ='Resumo M.O'!$D$31 -> 1526.3289 | O17: ='Resumo Custos Variáveis'!$F$21 -> 0 | P17: ='Outros Custos'!$D$31 -> 0 | Q17: =Transporte!$D$20 -> 0 | R17: =Manutenção!$D$21 -> 0 | S17: =I17 -> 0 | T17: =SUM(L17:S17) -> 3433.6711 | U17: =IF($L$2>=1,T17/$A$5,0) -> 0 | V17: ='Pré Tratamento Verniz'!M14 -> 140 | W17: ='Resumo M.O'!$E$27 -> 1907.3422 | X17: ='Resumo M.O'!$E$31 -> 1526.3289 | Y17: ='Resumo Custos Variáveis'!$G$21 -> 2404.5263 | Z17: ='Outros Custos'!$E$31 -> 0 | AA17: =Transporte!$E$20 -> 0 | AB17: =Manutenção!$E$21 -> 0 | AC17: =S17 -> 0 | AD17: =SUM(V17:AC17) -> 5978.1974 | AE17: =IF($L$2>=1,AD17/$A$5,0) -> 0 | AF17: ='Pré Tratamento Verniz'!P14 -> 0 | AG17: ='Resumo M.O'!$F$27 -> 1907.3422 | AH17: ='Resumo M.O'!$F$31 -> 1526.3289 | AI17: ='Resumo Custos Variáveis'!$H$21 -> 1573.8421 | AJ17: ='Outros Custos'!$F$31 -> 0 | AK17: =Transporte!$F$20 -> 0 | AL17: =Manutenção!$F$21 -> 0 | AM17: =AC17 -> 0 | AN17: =SUM(AF17:AM17) -> 5007.5132 | AO17: =IF($L$2>=1,AN17/$A$5,0) -> 0 | AP17: ='Pré Tratamento Verniz'!S14 -> 0 | AQ17: ='Resumo M.O'!$G$27 -> 1907.3422 | AR17: ='Resumo M.O'!$G$31 -> 1526.3289 | AS17: ='Resumo Custos Variáveis'!$I$21 -> 0 | AT17: ='Outros Custos'!$G$31 -> 0 | AU17: =Transporte!$G$20 -> 0 | AV17: =Manutenção!$G$21 -> 0 | AW17: =AM17 -> 0 | AX17: =SUM(AP17:AW17) -> 3433.6711 | AY17: =IF($L$2>=1,AX17/$A$5,0) -> 0 | AZ17: ='Pré Tratamento Verniz'!V14 -> 0 | BA17: ='Resumo M.O'!$H$27 -> 1907.3422 | BB17: ='Resumo M.O'!$H$31 -> 1526.3289 | BC17: ='Resumo Custos Variáveis'!$J$21 -> 0 | BD17: ='Outros Custos'!$H$31 -> 0 | BE17: =Transporte!$H$20 -> 0 | BF17: =Manutenção!$H$21 -> 3061.5385 | BG17: =AW17 -> 0 | BH17: =SUM(AZ17:BG17) -> 6495.2095 | BI17: =IF($L$2>=1,BH17/$A$5,0) -> 0 | BJ17: ='Pré Tratamento Verniz'!Y14 -> 0 | BK17: ='Resumo M.O'!$I$27 -> 1907.3422 | BL17: ='Resumo M.O'!$I$31 -> 1526.3289 | BM17: ='Resumo Custos Variáveis'!$K$21 -> 0 | BN17: ='Outros Custos'!$I$31 -> 0 | BO17: =Transporte!$I$20 -> 0 | BP17: =Manutenção!$I$21 -> 3030.7692 | BQ17: =BG17 -> 0 | BR17: =SUM(BJ17:BQ17) -> 6464.4403 | BS17: =IF($L$2>=1,BR17/$A$5,0) -> 0 | BT17: ='Pré Tratamento Verniz'!AB14 -> 0 | BU17: ='Resumo M.O'!$J$27 -> 1907.3422 | BV17: ='Resumo M.O'!$J$31 -> 1526.3289 | BW17: ='Resumo Custos Variáveis'!$L$21 -> 0 | BX17: ='Outros Custos'!$J$31 -> 0 | BY17: =Transporte!$J$20 -> 0 | BZ17: =Manutenção!$J$21 -> 0 | CA17: =BQ17 -> 0 | CB17: =SUM(BT17:CA17) -> 3433.6711 | CC17: =IF($L$2>=1,CB17/$A$5,0) -> 0 | CD17: ='Pré Tratamento Verniz'!AE14 -> 0 | CE17: ='Resumo M.O'!$K$27 -> 1907.3422 | CF17: ='Resumo M.O'!$K$31 -> 1526.3289 | CG17: ='Resumo Custos Variáveis'!$M$21 -> 0 | CH17: ='Outros Custos'!$K$31 -> 0 | CI17: =Transporte!$K$20 -> 0 | CJ17: =Manutenção!$K$21 -> 0 | CK17: =CA17 -> 0 | CL17: =SUM(CD17:CK17) -> 3433.6711 | CM17: =IF($L$2>=1,CL17/$A$5,0) -> 0 | CN17: ='Pré Tratamento Verniz'!AH14 -> 0 | CO17: ='Resumo M.O'!$L$27 -> 1907.3422 | CP17: ='Resumo M.O'!$L$31 -> 1526.3289 | CQ17: ='Resumo Custos Variáveis'!$N$21 -> 0 | CR17: ='Outros Custos'!$L$31 -> 0 | CS17: =Transporte!$L$20 -> 0 | CT17: =Manutenção!$L$21 -> 0 | CU17: =CK17 -> 0 | CV17: =SUM(CN17:CU17) -> 3433.6711 | CW17: =IF($L$2>=1,CV17/$A$5,0) -> 0 | CX17: ='Pré Tratamento Verniz'!AK14 -> 0 | CY17: ='Resumo M.O'!$M$27 -> 1907.3422 | CZ17: ='Resumo M.O'!$M$31 -> 1526.3289 | DA17: ='Resumo Custos Variáveis'!$O$21 -> 0 | DB17: ='Outros Custos'!$M$31 -> 0 | DC17: =Transporte!$M$20 -> 0 | DD17: =Manutenção!$M$21 -> 0 | DE17: =CU17 -> 0 | DF17: =SUM(CX17:DE17) -> 3433.6711 | DG17: =IF($L$2>=1,DF17/$A$5,0) -> 0 | DH17: ='Pré Tratamento Verniz'!AN14 -> 0 | DI17: ='Resumo M.O'!$N$27 -> 1907.3422 | DJ17: ='Resumo M.O'!$N$31 -> 1526.3289 | DK17: ='Resumo Custos Variáveis'!$P$21 -> 0 | DL17: ='Outros Custos'!$N$31 -> 0 | DM17: =Transporte!$N$20 -> 0 | DN17: =Manutenção!$N$21 -> 0 | DO17: =DE17 -> 0 | DP17: =SUM(DH17:DO17) -> 3433.6711 | DQ17: =IF($L$2>=1,DP17/$A$5,0) -> 0 | DS17: =K17 -> 0 | DT17: =U17 -> 0 | DU17: =AE17 -> 0 | DV17: =AO17 -> 0 | DW17: =AY17 -> 0 | DX17: =BI17 -> 0 | DY17: =BS17 -> 0 | DZ17: =CC17 -> 0 | EA17: =CM17 -> 0 | EB17: =CW17 -> 0 | EC17: =DG17 -> 0 | ED17: =DQ17 -> 0 | EF17: =B17/$A$5 -> 0 | EG17: =L17/$A$5 -> 0 | EH17: =V17/$A$5 -> 0.63636364 | EI17: =AF17/$A$5 -> 0 | EJ17: =AP17/$A$5 -> 0 | EK17: =AZ17/$A$5 -> 0 | EL17: =BJ17/$A$5 -> 0 | EM17: =BT17/$A$5 -> 0 | EN17: =CD17/$A$5 -> 0 | EO17: =CN17/$A$5 -> 0 | EP17: =CX17/$A$5 -> 0 | EQ17: =DH17/$A$5 -> 0
A18: Cobre Gold 15 | B18: ='Verniz Cataforético'!F11 -> 0 | C18: ='Resumo M.O'!$C$27 -> 1907.3422 | D18: ='Resumo M.O'!$C$31 -> 1526.3289 | E18: ='Resumo Custos Variáveis'!$E$21 -> 0 | F18: ='Outros Custos'!$C$31 -> 0 | G18: =Transporte!$C$20 -> 0 | H18: =Manutenção!$C$21 -> 0 | I18: =Investimentos!O10 -> 0 | J18: =SUM(B18:I18) -> 3433.6711 | K18: =IF($L$2>=1,J18/$A$5,0) -> 0 | L18: ='Verniz Cataforético'!I11 -> 0 | M18: ='Resumo M.O'!$D$27 -> 1907.3422 | N18: ='Resumo M.O'!$D$31 -> 1526.3289 | O18: ='Resumo Custos Variáveis'!$F$21 -> 0 | P18: ='Outros Custos'!$D$31 -> 0 | Q18: =Transporte!$D$20 -> 0 | R18: =Manutenção!$D$21 -> 0 | S18: =I18 -> 0 | T18: =SUM(L18:S18) -> 3433.6711 | U18: =IF($L$2>=1,T18/$A$5,0) -> 0 | V18: ='Verniz Cataforético'!L11 -> 23978.81 | W18: ='Resumo M.O'!$E$27 -> 1907.3422 | X18: ='Resumo M.O'!$E$31 -> 1526.3289 | Y18: ='Resumo Custos Variáveis'!$G$21 -> 2404.5263 | Z18: ='Outros Custos'!$E$31 -> 0 | AA18: =Transporte!$E$20 -> 0 | AB18: =Manutenção!$E$21 -> 0 | AC18: =S18 -> 0 | AD18: =SUM(V18:AC18) -> 29817.007 | AE18: =IF($L$2>=1,AD18/$A$5,0) -> 0 | AF18: ='Verniz Cataforético'!O11 -> 15749.42 | AG18: ='Resumo M.O'!$F$27 -> 1907.3422 | AH18: ='Resumo M.O'!$F$31 -> 1526.3289 | AI18: ='Resumo Custos Variáveis'!$H$21 -> 1573.8421 | AJ18: ='Outros Custos'!$F$31 -> 0 | AK18: =Transporte!$F$20 -> 0 | AL18: =Manutenção!$F$21 -> 0 | AM18: =AC18 -> 0 | AN18: =SUM(AF18:AM18) -> 20756.933 | AO18: =IF($L$2>=1,AN18/$A$5,0) -> 0 | AP18: ='Verniz Cataforético'!R11 -> 0 | AQ18: ='Resumo M.O'!$G$27 -> 1907.3422 | AR18: ='Resumo M.O'!$G$31 -> 1526.3289 | AS18: ='Resumo Custos Variáveis'!$I$21 -> 0 | AT18: ='Outros Custos'!$G$31 -> 0 | AU18: =Transporte!$G$20 -> 0 | AV18: =Manutenção!$G$21 -> 0 | AW18: =AM18 -> 0 | AX18: =SUM(AP18:AW18) -> 3433.6711 | AY18: =IF($L$2>=1,AX18/$A$5,0) -> 0 | AZ18: ='Verniz Cataforético'!U11 -> 0 | BA18: ='Resumo M.O'!$H$27 -> 1907.3422 | BB18: ='Resumo M.O'!$H$31 -> 1526.3289 | BC18: ='Resumo Custos Variáveis'!$J$21 -> 0 | BD18: ='Outros Custos'!$H$31 -> 0 | BE18: =Transporte!$H$20 -> 0 | BF18: =Manutenção!$H$21 -> 3061.5385 | BG18: =AW18 -> 0 | BH18: =SUM(AZ18:BG18) -> 6495.2095 | BI18: =IF($L$2>=1,BH18/$A$5,0) -> 0 | BJ18: ='Verniz Cataforético'!X11 -> 0 | BK18: ='Resumo M.O'!$I$27 -> 1907.3422 | BL18: ='Resumo M.O'!$I$31 -> 1526.3289 | BM18: ='Resumo Custos Variáveis'!$K$21 -> 0 | BN18: ='Outros Custos'!$I$31 -> 0 | BO18: =Transporte!$I$20 -> 0 | BP18: =Manutenção!$I$21 -> 3030.7692 | BQ18: =BG18 -> 0 | BR18: =SUM(BJ18:BQ18) -> 6464.4403 | BS18: =IF($L$2>=1,BR18/$A$5,0) -> 0 | BT18: ='Verniz Cataforético'!AA11 -> 0 | BU18: ='Resumo M.O'!$J$27 -> 1907.3422 | BV18: ='Resumo M.O'!$J$31 -> 1526.3289 | BW18: ='Resumo Custos Variáveis'!$L$21 -> 0 | BX18: ='Outros Custos'!$J$31 -> 0 | BY18: =Transporte!$J$20 -> 0 | BZ18: =Manutenção!$J$21 -> 0 | CA18: =BQ18 -> 0 | CB18: =SUM(BT18:CA18) -> 3433.6711 | CC18: =IF($L$2>=1,CB18/$A$5,0) -> 0 | CD18: ='Verniz Cataforético'!AD11 -> 0 | CE18: ='Resumo M.O'!$K$27 -> 1907.3422 | CF18: ='Resumo M.O'!$K$31 -> 1526.3289 | CG18: ='Resumo Custos Variáveis'!$M$21 -> 0 | CH18: ='Outros Custos'!$K$31 -> 0 | CI18: =Transporte!$K$20 -> 0 | CJ18: =Manutenção!$K$21 -> 0 | CK18: =CA18 -> 0 | CL18: =SUM(CD18:CK18) -> 3433.6711 | CM18: =IF($L$2>=1,CL18/$A$5,0) -> 0 | CN18: ='Verniz Cataforético'!AG11 -> 0 | CO18: ='Resumo M.O'!$L$27 -> 1907.3422 | CP18: ='Resumo M.O'!$L$31 -> 1526.3289 | CQ18: ='Resumo Custos Variáveis'!$N$21 -> 0 | CR18: ='Outros Custos'!$L$31 -> 0 | CS18: =Transporte!$L$20 -> 0 | CT18: =Manutenção!$L$21 -> 0 | CU18: =CK18 -> 0 | CV18: =SUM(CN18:CU18) -> 3433.6711 | CW18: =IF($L$2>=1,CV18/$A$5,0) -> 0 | CX18: ='Verniz Cataforético'!AJ11 -> 0 | CY18: ='Resumo M.O'!$M$27 -> 1907.3422 | CZ18: ='Resumo M.O'!$M$31 -> 1526.3289 | DA18: ='Resumo Custos Variáveis'!$O$21 -> 0 | DB18: ='Outros Custos'!$M$31 -> 0 | DC18: =Transporte!$M$20 -> 0 | DD18: =Manutenção!$M$21 -> 0 | DE18: =CU18 -> 0 | DF18: =SUM(CX18:DE18) -> 3433.6711 | DG18: =IF($L$2>=1,DF18/$A$5,0) -> 0 | DH18: ='Verniz Cataforético'!AM11 -> 0 | DI18: ='Resumo M.O'!$N$27 -> 1907.3422 | DJ18: ='Resumo M.O'!$N$31 -> 1526.3289 | DK18: ='Resumo Custos Variáveis'!$P$21 -> 0 | DL18: ='Outros Custos'!$N$31 -> 0 | DM18: =Transporte!$N$20 -> 0 | DN18: =Manutenção!$N$21 -> 0 | DO18: =DE18 -> 0 | DP18: =SUM(DH18:DO18) -> 3433.6711 | DQ18: =IF($L$2>=1,DP18/$A$5,0) -> 0 | DS18: =K18 -> 0 | DT18: =U18 -> 0 | DU18: =AE18 -> 0 | DV18: =AO18 -> 0 | DW18: =AY18 -> 0 | DX18: =BI18 -> 0 | DY18: =BS18 -> 0 | DZ18: =CC18 -> 0 | EA18: =CM18 -> 0 | EB18: =CW18 -> 0 | EC18: =DG18 -> 0 | ED18: =DQ18 -> 0 | EF18: =B18/$A$5 -> 0 | EG18: =L18/$A$5 -> 0 | EH18: =V18/$A$5 -> 108.99459 | EI18: =AF18/$A$5 -> 71.588273 | EJ18: =AP18/$A$5 -> 0 | EK18: =AZ18/$A$5 -> 0 | EL18: =BJ18/$A$5 -> 0 | EM18: =BT18/$A$5 -> 0 | EN18: =CD18/$A$5 -> 0 | EO18: =CN18/$A$5 -> 0 | EP18: =CX18/$A$5 -> 0 | EQ18: =DH18/$A$5 -> 0
