Workbook

Sheet Menu
A1: B

Sheet Resumo de Custo
A2: Menu | E2: Resumo de Custo | K2: =TODAY() -> 46114 | L2: =K3-K2 -> -108
K3: 46006
A4: Horas Trabalhadas
A5: 220
B6: Janeiro | L6: Fevereiro | V6: Março | AF6: Abril | AP6: Maio | AZ6: Junho | BJ6: Julho | BT6: Agosto | CD6: Setembro | CN6: Outubro | CX6: Novembro | DH6: Dezembro | DV6: Custo Total | EI6: Custo Produto Químico
A7: Linha | B7: Produto Químico | C7: M.O.D | D7: M.O.I | E7: Custo Variáveis | F7: Outros Custos | G7: Transporte | H7: Manutenção | I7: Investimentos | J7: Total | K7: Custo Hora | L7: Produto Químico | M7: M.O.D | N7: M.O.I | O7: Custo Variáveis | P7: Outros Custos | Q7: Transporte | R7: Manutenção | S7: Investimentos | T7: Total | U7: Custo Hora | V7: Produto Químico | W7: M.O.D | X7: M.O.I | Y7: Custo Variáveis | Z7: Outros Custos | AA7: Transporte | AB7: Manutenção | AC7: Investimentos | AD7: Total | AE7: Custo Hora | AF7: Produto Químico | AG7: M.O.D | AH7: M.O.I | AI7: Custo Variáveis | AJ7: Outros Custos | AK7: Transporte | AL7: Manutenção | AM7: Investimentos | AN7: Total | AO7: Custo Hora | AP7: Produto Químico | AQ7: M.O.D | AR7: M.O.I | AS7: Custo Variáveis | AT7: Outros Custos | AU7: Transporte | AV7: Manutenção | AW7: Investimentos | AX7: Total | AY7: Custo Hora | AZ7: Produto Químico | BA7: M.O.D | BB7: M.O.I | BC7: Custo Variáveis | BD7: Outros Custos | BE7: Transporte | BF7: Manutenção | BG7: Investimentos | BH7: Total | BI7: Custo Hora | BJ7: Produto Químico | BK7: M.O.D | BL7: M.O.I | BM7: Custo Variáveis | BN7: Outros Custos | BO7: Transporte | BP7: Manutenção | BQ7: Investimentos | BR7: Total | BS7: Custo Hora | BT7: Produto Químico | BU7: M.O.D | BV7: M.O.I | BW7: Custo Variáveis | BX7: Outros Custos | BY7: Transporte | BZ7: Manutenção | CA7: Investimentos | CB7: Total | CC7: Custo Hora | CD7: Produto Químico | CE7: M.O.D | CF7: M.O.I | CG7: Custo Variáveis | CH7: Outros Custos | CI7: Transporte | CJ7: Manutenção | CK7: Investimentos | CL7: Total | CM7: Custo Hora | CN7: Produto Químico | CO7: M.O.D | CP7: M.O.I | CQ7: Custo Variáveis | CR7: Outros Custos | CS7: Transporte | CT7: Manutenção | CU7: Investimentos | CV7: Total | CW7: Custo Hora | CX7: Produto Químico | CY7: M.O.D | CZ7: M.O.I | DA7: Custo Variáveis | DB7: Outros Custos | DC7: Transporte | DD7: Manutenção | DE7: Investimentos | DF7: Total | DG7: Custo Hora | DH7: Produto Químico | DI7: M.O.D | DJ7: M.O.I | DK7: Custo Variáveis | DL7: Outros Custos | DM7: Transporte | DN7: Manutenção | DO7: Investimentos | DP7: Total | DQ7: Custo Hora | DS7: Jan | DT7: Fev | DU7: Mar | DV7: Abr | DW7: Mai | DX7: Jun | DY7: Jul | DZ7: Ago | EA7: Set | EB7: Out | EC7: Nov | ED7: Dez | EF7: Jan | EG7: Fev | EH7: Mar | EI7: Abr | EJ7: Mai | EK7: Jun | EL7: Jul | EM7: Ago | EN7: Set | EO7: Out | EP7: Nov | EQ7: Dez
A8: Linha 1 Zn Alc. Aut | B8: ='Lnha 1 Zn Alc. Aut'!G15 -> 0 | C8: ='Resumo M.O'!C2 -> 5410.4181 | D8: ='Resumo M.O'!$C$13 -> 9143.3131 | E8: ='Resumo Custos Variáveis'!$E$21 -> 0 | F8: ='Outros Custos'!$C$31 -> 0 | G8: =Transporte!$C$20 -> 0 | H8: =Manutenção!$C$21 -> 0 | I8: =Investimentos!G10 -> 0 | J8: =SUM(B8:I8) -> 14553.731 | K8: =IF($L$2>=1,J8/$A$5,0) -> 0 | L8: ='Lnha 1 Zn Alc. Aut'!J15 -> 0 | M8: ='Resumo M.O'!D2 -> 5410.4181 | N8: ='Resumo M.O'!$D$13 -> 9143.3131 | O8: ='Resumo Custos Variáveis'!$F$21 -> 0 | P8: ='Outros Custos'!$D$31 -> 0 | Q8: =Transporte!$D$20 -> 0 | R8: =Manutenção!$D$21 -> 0 | S8: =I8 -> 0 | T8: =SUM(L8:S8) -> 14553.731 | U8: =IF($L$2>=1,T8/$A$5,0) -> 0 | V8: ='Lnha 1 Zn Alc. Aut'!M15 -> 0 | W8: ='Resumo M.O'!E2 -> 5410.4181 | X8: ='Resumo M.O'!$E$13 -> 9143.3131 | Y8: ='Resumo Custos Variáveis'!$G$21 -> 0 | Z8: ='Outros Custos'!$E$31 -> 0 | AA8: =Transporte!$E$20 -> 0 | AB8: =Manutenção!$E$21 -> 0 | AC8: =S8 -> 0 | AD8: =SUM(V8:AC8) -> 14553.731 | AE8: =IF($L$2>=1,AD8/$A$5,0) -> 0 | AF8: ='Lnha 1 Zn Alc. Aut'!P15 -> 0 | AG8: ='Resumo M.O'!F2 -> 5410.4181 | AH8: ='Resumo M.O'!$F$13 -> 9143.3131 | AI8: ='Resumo Custos Variáveis'!$H$21 -> 0 | AJ8: ='Outros Custos'!$F$31 -> 0 | AK8: =Transporte!$F$20 -> 0 | AL8: =Manutenção!$F$21 -> 0 | AM8: =AC8 -> 0 | AN8: =SUM(AF8:AM8) -> 14553.731 | AO8: =IF(L2>=1,AN8/$A$5,0) -> 0 | AP8: ='Lnha 1 Zn Alc. Aut'!S15 -> 0 | AQ8: ='Resumo M.O'!G2 -> 5410.4181 | AR8: ='Resumo M.O'!$G$13 -> 9143.3131 | AS8: ='Resumo Custos Variáveis'!$I$21 -> 0 | AT8: ='Outros Custos'!$G$31 -> 0 | AU8: =Transporte!$G$20 -> 0 | AV8: =Manutenção!$G$21 -> 0 | AW8: =AM8 -> 0 | AX8: =SUM(AP8:AW8) -> 14553.731 | AY8: =IF(L2>=1,AX8/$A$5,0) -> 0 | AZ8: ='Lnha 1 Zn Alc. Aut'!V15 -> 0 | BA8: ='Resumo M.O'!H2 -> 5410.4181 | BB8: ='Resumo M.O'!$H$13 -> 9143.3131 | BC8: ='Resumo Custos Variáveis'!$J$21 -> 0 | BD8: ='Outros Custos'!$H$31 -> 0 | BE8: =Transporte!$H$20 -> 0 | BF8: =Manutenção!$H$21 -> 0 | BG8: =AW8 -> 0 | BH8: =SUM(AZ8:BG8) -> 14553.731 | BI8: =IF(L2>=1,BH8/$A$5,0) -> 0 | BJ8: ='Lnha 1 Zn Alc. Aut'!Y15 -> 0 | BK8: ='Resumo M.O'!I2 -> 5410.4181 | BL8: ='Resumo M.O'!$I$13 -> 9143.3131 | BM8: ='Resumo Custos Variáveis'!$K$21 -> 0 | BN8: ='Outros Custos'!$I$31 -> 0 | BO8: =Transporte!$I$20 -> 0 | BP8: =Manutenção!$I$21 -> 0 | BQ8: =BG8 -> 0 | BR8: =SUM(BJ8:BQ8) -> 14553.731 | BS8: =IF(L2>=1,BR8/$A$5,0) -> 0 | BT8: ='Lnha 1 Zn Alc. Aut'!AB15 -> 0 | BU8: ='Resumo M.O'!J2 -> 5410.4181 | BV8: ='Resumo M.O'!$J$13 -> 9143.3131 | BW8: ='Resumo Custos Variáveis'!$L$21 -> 0 | BX8: ='Outros Custos'!$J$31 -> 0 | BY8: =Transporte!$J$20 -> 0 | BZ8: =Manutenção!$J$21 -> 0 | CA8: =BQ8 -> 0 | CB8: =SUM(BT8:CA8) -> 14553.731 | CC8: =IF(L2>=1,CB8/$A$5,0) -> 0 | CD8: ='Lnha 1 Zn Alc. Aut'!AE15 -> 0 | CE8: ='Resumo M.O'!K2 -> 5410.4181 | CF8: ='Resumo M.O'!$K$13 -> 9143.3131 | CG8: ='Resumo Custos Variáveis'!$M$21 -> 4328.5714 | CH8: ='Outros Custos'!$K$31 -> 2140 | CI8: =Transporte!$K$20 -> 0 | CJ8: =Manutenção!$K$21 -> 10000 | CK8: =CA8 -> 0 | CL8: =SUM(CD8:CK8) -> 31022.303 | CM8: =IF(L2>=1,CL8/$A$5,0) -> 0 | CN8: ='Lnha 1 Zn Alc. Aut'!AH15 -> 0 | CO8: ='Resumo M.O'!L2 -> 5410.4181 | CP8: ='Resumo M.O'!$L$13 -> 9143.3131 | CQ8: ='Resumo Custos Variáveis'!$N$21 -> 0 | CR8: ='Outros Custos'!$L$31 -> 0 | CS8: =Transporte!$L$20 -> 0 | CT8: =Manutenção!$L$21 -> 10000 | CU8: =CK8 -> 0 | CV8: =SUM(CN8:CU8) -> 24553.731 | CW8: =IF(L2>=1,CV8/$A$5,0) -> 0 | CX8: ='Lnha 1 Zn Alc. Aut'!AK15 -> 0 | CY8: ='Resumo M.O'!M2 -> 5410.4181 | CZ8: ='Resumo M.O'!$M$13 -> 9143.3131 | DA8: ='Resumo Custos Variáveis'!$O$21 -> 0 | DB8: ='Outros Custos'!$M$31 -> 0 | DC8: =Transporte!$M$20 -> 0 | DD8: =Manutenção!$M$21 -> 10000 | DE8: =CU8 -> 0 | DF8: =SUM(CX8:DE8) -> 24553.731 | DG8: =IF(L2>=1,DF8/$A$5,0) -> 0 | DH8: ='Lnha 1 Zn Alc. Aut'!AN15 -> 0 | DI8: ='Resumo M.O'!N2 -> 5410.4181 | DJ8: ='Resumo M.O'!$N$13 -> 9143.3131 | DK8: ='Resumo Custos Variáveis'!$P$21 -> 0 | DL8: ='Outros Custos'!$N$31 -> 0 | DM8: =Transporte!$N$20 -> 0 | DN8: =Manutenção!$N$21 -> 10000 | DO8: =DE8 -> 0 | DP8: =SUM(DH8:DO8) -> 24553.731 | DQ8: =IF(L2>=1,DP8/$A$5,0) -> 0 | DS8: =K8 -> 0 | DT8: =U8 -> 0 | DU8: =AE8 -> 0 | DV8: =AO8 -> 0 | DW8: =AY8 -> 0 | DX8: =BI8 -> 0 | DY8: =BS8 -> 0 | DZ8: =CC8 -> 0 | EA8: =CM8 -> 0 | EB8: =CW8 -> 0 | EC8: =DG8 -> 0 | ED8: =DQ8 -> 0 | EF8: =B8/$A$5 -> 0 | EG8: =L8/$A$5 -> 0 | EH8: =V8/$A$5 -> 0 | EI8: =AF8/$A$5 -> 0 | EJ8: =AP8/$A$5 -> 0 | EK8: =AZ8/$A$5 -> 0 | EL8: =BJ8/$A$5 -> 0 | EM8: =BT8/$A$5 -> 0 | EN8: =CD8/$A$5 -> 0 | EO8: =CN8/$A$5 -> 0 | EP8: =CX8/$A$5 -> 0 | EQ8: =DH8/$A$5 -> 0
A9: Linha 2 Zn Alc. Aut | B9: ='Linha 2 Zn Alc. Aut'!G16 -> 0 | C9: ='Resumo M.O'!C3 -> 5410.4043 | D9: ='Resumo M.O'!$C$13 -> 9143.3131 | E9: ='Resumo Custos Variáveis'!$E$21 -> 0 | F9: ='Outros Custos'!$C$31 -> 0 | G9: =Transporte!$C$20 -> 0 | H9: =Manutenção!$C$21 -> 0 | I9: =Investimentos!G15 -> 0 | J9: =SUM(B9:I9) -> 14553.717 | K9: =IF($L$2>=1,J9/$A$5,0) -> 0 | L9: ='Linha 2 Zn Alc. Aut'!J16 -> 0 | M9: ='Resumo M.O'!D3 -> 5410.4043 | N9: ='Resumo M.O'!$D$13 -> 9143.3131 | O9: ='Resumo Custos Variáveis'!$F$21 -> 0 | P9: ='Outros Custos'!$D$31 -> 0 | Q9: =Transporte!$D$20 -> 0 | R9: =Manutenção!$D$21 -> 0 | S9: =I9 -> 0 | T9: =SUM(L9:S9) -> 14553.717 | U9: =IF($L$2>=1,T9/$A$5,0) -> 0 | V9: ='Linha 2 Zn Alc. Aut'!M16 -> 0 | W9: ='Resumo M.O'!E3 -> 5410.4043 | X9: ='Resumo M.O'!$E$13 -> 9143.3131 | Y9: ='Resumo Custos Variáveis'!$G$21 -> 0 | Z9: ='Outros Custos'!$E$31 -> 0 | AA9: =Transporte!$E$20 -> 0 | AB9: =Manutenção!$E$21 -> 0 | AC9: =S9 -> 0 | AD9: =SUM(V9:AC9) -> 14553.717 | AE9: =IF($L$2>=1,AD9/$A$5,0) -> 0 | AF9: ='Linha 2 Zn Alc. Aut'!P16 -> 0 | AG9: ='Resumo M.O'!F3 -> 5410.4043 | AH9: ='Resumo M.O'!$F$13 -> 9143.3131 | AI9: ='Resumo Custos Variáveis'!$H$21 -> 0 | AJ9: ='Outros Custos'!$F$31 -> 0 | AK9: =Transporte!$F$20 -> 0 | AL9: =Manutenção!$F$21 -> 0 | AM9: =AC9 -> 0 | AN9: =SUM(AF9:AM9) -> 14553.717 | AO9: =IF(L2>=1,AN9/$A$5,0) -> 0 | AP9: ='Linha 2 Zn Alc. Aut'!S16 -> 0 | AQ9: ='Resumo M.O'!G3 -> 5410.4043 | AR9: ='Resumo M.O'!$G$13 -> 9143.3131 | AS9: ='Resumo Custos Variáveis'!$I$21 -> 0 | AT9: ='Outros Custos'!$G$31 -> 0 | AU9: =Transporte!$G$20 -> 0 | AV9: =Manutenção!$G$21 -> 0 | AW9: =AM9 -> 0 | AX9: =SUM(AP9:AW9) -> 14553.717 | AY9: =IF(L2>=1,AX9/$A$5,0) -> 0 | AZ9: ='Linha 2 Zn Alc. Aut'!V16 -> 0 | BA9: ='Resumo M.O'!H3 -> 5410.4043 | BB9: ='Resumo M.O'!$H$13 -> 9143.3131 | BC9: ='Resumo Custos Variáveis'!$J$21 -> 0 | BD9: ='Outros Custos'!$H$31 -> 0 | BE9: =Transporte!$H$20 -> 0 | BF9: =Manutenção!$H$21 -> 0 | BG9: =AW9 -> 0 | BH9: =SUM(AZ9:BG9) -> 14553.717 | BI9: =IF(L2>=1,BH9/$A$5,0) -> 0 | BJ9: ='Linha 2 Zn Alc. Aut'!Y16 -> 0 | BK9: ='Resumo M.O'!I3 -> 5410.4043 | BL9: ='Resumo M.O'!$I$13 -> 9143.3131 | BM9: ='Resumo Custos Variáveis'!$K$21 -> 0 | BN9: ='Outros Custos'!$I$31 -> 0 | BO9: =Transporte!$I$20 -> 0 | BP9: =Manutenção!$I$21 -> 0 | BQ9: =BG9 -> 0 | BR9: =SUM(BJ9:BQ9) -> 14553.717 | BS9: =IF(L2>=1,BR9/$A$5,0) -> 0 | BT9: ='Linha 2 Zn Alc. Aut'!AB16 -> 0 | BU9: ='Resumo M.O'!J3 -> 5410.4043 | BV9: ='Resumo M.O'!$J$13 -> 9143.3131 | BW9: ='Resumo Custos Variáveis'!$L$21 -> 0 | BX9: ='Outros Custos'!$J$31 -> 0 | BY9: =Transporte!$J$20 -> 0 | BZ9: =Manutenção!$J$21 -> 0 | CA9: =BQ9 -> 0 | CB9: =SUM(BT9:CA9) -> 14553.717 | CC9: =IF(L2>=1,CB9/$A$5,0) -> 0 | CD9: ='Linha 2 Zn Alc. Aut'!AE16 -> 0 | CE9: ='Resumo M.O'!K3 -> 5410.4043 | CF9: ='Resumo M.O'!$K$13 -> 9143.3131 | CG9: ='Resumo Custos Variáveis'!$M$21 -> 4328.5714 | CH9: ='Outros Custos'!$K$31 -> 2140 | CI9: =Transporte!$K$20 -> 0 | CJ9: =Manutenção!$K$21 -> 10000 | CK9: =CA9 -> 0 | CL9: =SUM(CD9:CK9) -> 31022.289 | CM9: =IF(L2>=1,CL9/$A$5,0) -> 0 | CN9: ='Linha 2 Zn Alc. Aut'!AH16 -> 0 | CO9: ='Resumo M.O'!L3 -> 5410.4043 | CP9: ='Resumo M.O'!$L$13 -> 9143.3131 | CQ9: ='Resumo Custos Variáveis'!$N$21 -> 0 | CR9: ='Outros Custos'!$L$31 -> 0 | CS9: =Transporte!$L$20 -> 0 | CT9: =Manutenção!$L$21 -> 10000 | CU9: =CK9 -> 0 | CV9: =SUM(CN9:CU9) -> 24553.717 | CW9: =IF(L2>=1,CV9/$A$5,0) -> 0 | CX9: ='Linha 2 Zn Alc. Aut'!AK16 -> 0 | CY9: ='Resumo M.O'!M3 -> 5410.4043 | CZ9: ='Resumo M.O'!$M$13 -> 9143.3131 | DA9: ='Resumo Custos Variáveis'!$O$21 -> 0 | DB9: ='Outros Custos'!$M$31 -> 0 | DC9: =Transporte!$M$20 -> 0 | DD9: =Manutenção!$M$21 -> 10000 | DE9: =CU9 -> 0 | DF9: =SUM(CX9:DE9) -> 24553.717 | DG9: =IF(L2>=1,DF9/$A$5,0) -> 0 | DH9: ='Linha 2 Zn Alc. Aut'!AN16 -> 0 | DI9: ='Resumo M.O'!N3 -> 5410.4043 | DJ9: ='Resumo M.O'!$N$13 -> 9143.3131 | DK9: ='Resumo Custos Variáveis'!$P$21 -> 0 | DL9: ='Outros Custos'!$N$31 -> 0 | DM9: =Transporte!$N$20 -> 0 | DN9: =Manutenção!$N$21 -> 10000 | DO9: =DE9 -> 0 | DP9: =SUM(DH9:DO9) -> 24553.717 | DQ9: =IF(L2>=1,DP9/$A$5,0) -> 0 | DS9: =K9 -> 0 | DT9: =U9 -> 0 | DU9: =AE9 -> 0 | DV9: =AO9 -> 0 | DW9: =AY9 -> 0 | DX9: =BI9 -> 0 | DY9: =BS9 -> 0 | DZ9: =CC9 -> 0 | EA9: =CM9 -> 0 | EB9: =CW9 -> 0 | EC9: =DG9 -> 0 | ED9: =DQ9 -> 0 | EF9: =B9/$A$5 -> 0 | EG9: =L9/$A$5 -> 0 | EH9: =V9/$A$5 -> 0 | EI9: =AF9/$A$5 -> 0 | EJ9: =AP9/$A$5 -> 0 | EK9: =AZ9/$A$5 -> 0 | EL9: =BJ9/$A$5 -> 0 | EM9: =BT9/$A$5 -> 0 | EN9: =CD9/$A$5 -> 0 | EO9: =CN9/$A$5 -> 0 | EP9: =CX9/$A$5 -> 0 | EQ9: =DH9/$A$5 -> 0
A10: Linha 3 Zn Alc. Aut | B10: ='Linha 3 Zn Alc. Aut'!G17 -> 0 | C10: ='Resumo M.O'!C4 -> 4028.0981 | D10: ='Resumo M.O'!$C$13 -> 9143.3131 | E10: ='Resumo Custos Variáveis'!$E$21 -> 0 | F10: ='Outros Custos'!$C$31 -> 0 | G10: =Transporte!$C$20 -> 0 | H10: =Manutenção!$C$21 -> 0 | I10: =Investimentos!G20 -> 0 | J10: =SUM(B10:I10) -> 13171.411 | K10: =IF($L$2>=1,J10/$A$5,0) -> 0 | L10: ='Linha 3 Zn Alc. Aut'!J17 -> 0 | M10: ='Resumo M.O'!D4 -> 4028.0981 | N10: ='Resumo M.O'!$D$13 -> 9143.3131 | O10: ='Resumo Custos Variáveis'!$F$21 -> 0 | P10: ='Outros Custos'!$D$31 -> 0 | Q10: =Transporte!$D$20 -> 0 | R10: =Manutenção!$D$21 -> 0 | S10: =I10 -> 0 | T10: =SUM(L10:S10) -> 13171.411 | U10: =IF($L$2>=1,T10/$A$5,0) -> 0 | V10: ='Linha 3 Zn Alc. Aut'!M17 -> 0 | W10: ='Resumo M.O'!E4 -> 4028.0981 | X10: ='Resumo M.O'!$E$13 -> 9143.3131 | Y10: ='Resumo Custos Variáveis'!$G$21 -> 0 | Z10: ='Outros Custos'!$E$31 -> 0 | AA10: =Transporte!$E$20 -> 0 | AB10: =Manutenção!$E$21 -> 0 | AC10: =S10 -> 0 | AD10: =SUM(V10:AC10) -> 13171.411 | AE10: =IF($L$2>=1,AD10/$A$5,0) -> 0 | AF10: ='Linha 3 Zn Alc. Aut'!P17 -> 0 | AG10: ='Resumo M.O'!F4 -> 4028.0981 | AH10: ='Resumo M.O'!$F$13 -> 9143.3131 | AI10: ='Resumo Custos Variáveis'!$H$21 -> 0 | AJ10: ='Outros Custos'!$F$31 -> 0 | AK10: =Transporte!$F$20 -> 0 | AL10: =Manutenção!$F$21 -> 0 | AM10: =AC10 -> 0 | AN10: =SUM(AF10:AM10) -> 13171.411 | AO10: =IF(L2>=1,AN10/$A$5,0) -> 0 | AP10: ='Linha 3 Zn Alc. Aut'!S17 -> 0 | AQ10: ='Resumo M.O'!G4 -> 4028.0981 | AR10: ='Resumo M.O'!$G$13 -> 9143.3131 | AS10: ='Resumo Custos Variáveis'!$I$21 -> 0 | AT10: ='Outros Custos'!$G$31 -> 0 | AU10: =Transporte!$G$20 -> 0 | AV10: =Manutenção!$G$21 -> 0 | AW10: =AM10 -> 0 | AX10: =SUM(AP10:AW10) -> 13171.411 | AY10: =IF(L2>=1,AX10/$A$5,0) -> 0 | AZ10: ='Linha 3 Zn Alc. Aut'!V17 -> 0 | BA10: ='Resumo M.O'!H4 -> 4028.0981 | BB10: ='Resumo M.O'!$H$13 -> 9143.3131 | BC10: ='Resumo Custos Variáveis'!$J$21 -> 0 | BD10: ='Outros Custos'!$H$31 -> 0 | BE10: =Transporte!$H$20 -> 0 | BF10: =Manutenção!$H$21 -> 0 | BG10: =AW10 -> 0 | BH10: =SUM(AZ10:BG10) -> 13171.411 | BI10: =IF(L2>=1,BH10/$A$5,0) -> 0 | BJ10: ='Linha 3 Zn Alc. Aut'!Y17 -> 0 | BK10: ='Resumo M.O'!I4 -> 4028.0981 | BL10: ='Resumo M.O'!$I$13 -> 9143.3131 | BM10: ='Resumo Custos Variáveis'!$K$21 -> 0 | BN10: ='Outros Custos'!$I$31 -> 0 | BO10: =Transporte!$I$20 -> 0 | BP10: =Manutenção!$I$21 -> 0 | BQ10: =BG10 -> 0 | BR10: =SUM(BJ10:BQ10) -> 13171.411 | BS10: =IF(L2>=1,BR10/$A$5,0) -> 0 | BT10: ='Linha 3 Zn Alc. Aut'!AB17 -> 0 | BU10: ='Resumo M.O'!J4 -> 4028.0981 | BV10: ='Resumo M.O'!$J$13 -> 9143.3131 | BW10: ='Resumo Custos Variáveis'!$L$21 -> 0 | BX10: ='Outros Custos'!$J$31 -> 0 | BY10: =Transporte!$J$20 -> 0 | BZ10: =Manutenção!$J$21 -> 0 | CA10: =BQ10 -> 0 | CB10: =SUM(BT10:CA10) -> 13171.411 | CC10: =IF(L2>=1,CB10/$A$5,0) -> 0 | CD10: ='Linha 3 Zn Alc. Aut'!AE17 -> 0 | CE10: ='Resumo M.O'!K4 -> 4028.0981 | CF10: ='Resumo M.O'!$K$13 -> 9143.3131 | CG10: ='Resumo Custos Variáveis'!$M$21 -> 4328.5714 | CH10: ='Outros Custos'!$K$31 -> 2140 | CI10: =Transporte!$K$20 -> 0 | CJ10: =Manutenção!$K$21 -> 10000 | CK10: =CA10 -> 0 | CL10: =SUM(CD10:CK10) -> 29639.983 | CM10: =IF(L2>=1,CL10/$A$5,0) -> 0 | CN10: ='Linha 3 Zn Alc. Aut'!AH17 -> 0 | CO10: ='Resumo M.O'!L4 -> 4028.0981 | CP10: ='Resumo M.O'!$L$13 -> 9143.3131 | CQ10: ='Resumo Custos Variáveis'!$N$21 -> 0 | CR10: ='Outros Custos'!$L$31 -> 0 | CS10: =Transporte!$L$20 -> 0 | CT10: =Manutenção!$L$21 -> 10000 | CU10: =CK10 -> 0 | CV10: =SUM(CN10:CU10) -> 23171.411 | CW10: =IF(L2>=1,CV10/$A$5,0) -> 0 | CX10: ='Linha 3 Zn Alc. Aut'!AK17 -> 0 | CY10: ='Resumo M.O'!M4 -> 4028.0981 | CZ10: ='Resumo M.O'!$M$13 -> 9143.3131 | DA10: ='Resumo Custos Variáveis'!$O$21 -> 0 | DB10: ='Outros Custos'!$M$31 -> 0 | DC10: =Transporte!$M$20 -> 0 | DD10: =Manutenção!$M$21 -> 10000 | DE10: =CU10 -> 0 | DF10: =SUM(CX10:DE10) -> 23171.411 | DG10: =IF(L2>=1,DF10/$A$5,0) -> 0 | DH10: ='Linha 3 Zn Alc. Aut'!AN17 -> 0 | DI10: ='Resumo M.O'!N4 -> 4028.0981 | DJ10: ='Resumo M.O'!$N$13 -> 9143.3131 | DK10: ='Resumo Custos Variáveis'!$P$21 -> 0 | DL10: ='Outros Custos'!$N$31 -> 0 | DM10: =Transporte!$N$20 -> 0 | DN10: =Manutenção!$N$21 -> 10000 | DO10: =DE10 -> 0 | DP10: =SUM(DH10:DO10) -> 23171.411 | DQ10: =IF(L2>=1,DP10/$A$5,0) -> 0 | DS10: =K10 -> 0 | DT10: =U10 -> 0 | DU10: =AE10 -> 0 | DV10: =AO10 -> 0 | DW10: =AY10 -> 0 | DX10: =BI10 -> 0 | DY10: =BS10 -> 0 | DZ10: =CC10 -> 0 | EA10: =CM10 -> 0 | EB10: =CW10 -> 0 | EC10: =DG10 -> 0 | ED10: =DQ10 -> 0 | EF10: =B10/$A$5 -> 0 | EG10: =L10/$A$5 -> 0 | EH10: =V10/$A$5 -> 0 | EI10: =AF10/$A$5 -> 0 | EJ10: =AP10/$A$5 -> 0 | EK10: =AZ10/$A$5 -> 0 | EL10: =BJ10/$A$5 -> 0 | EM10: =BT10/$A$5 -> 0 | EN10: =CD10/$A$5 -> 0 | EO10: =CN10/$A$5 -> 0 | EP10: =CX10/$A$5 -> 0 | EQ10: =DH10/$A$5 -> 0
A11: Linha 4 Zn Alc. Manual | B11: =+'Linha 4 Zn Alc. Manual'!G15 -> 0 | C11: ='Resumo M.O'!C5 -> 3961.4925 | D11: ='Resumo M.O'!$C$13 -> 9143.3131 | E11: ='Resumo Custos Variáveis'!$E$21 -> 0 | F11: ='Outros Custos'!$C$31 -> 0 | G11: =Transporte!$C$20 -> 0 | H11: =Manutenção!$C$21 -> 0 | I11: =Investimentos!G27 -> 0 | J11: =SUM(B11:I11) -> 13104.806 | K11: =IF($L$2>=1,J11/$A$5,0) -> 0 | L11: ='Linha 4 Zn Alc. Manual'!J15 -> 0 | M11: ='Resumo M.O'!D5 -> 3961.4925 | N11: ='Resumo M.O'!$D$13 -> 9143.3131 | O11: ='Resumo Custos Variáveis'!$F$21 -> 0 | P11: ='Outros Custos'!$D$31 -> 0 | Q11: =Transporte!$D$20 -> 0 | R11: =Manutenção!$D$21 -> 0 | S11: =I11 -> 0 | T11: =SUM(L11:S11) -> 13104.806 | U11: =IF($L$2>=1,T11/$A$5,0) -> 0 | V11: ='Linha 4 Zn Alc. Manual'!M15 -> 0 | W11: ='Resumo M.O'!E5 -> 3961.4925 | X11: ='Resumo M.O'!$E$13 -> 9143.3131 | Y11: ='Resumo Custos Variáveis'!$G$21 -> 0 | Z11: ='Outros Custos'!$E$31 -> 0 | AA11: =Transporte!$E$20 -> 0 | AB11: =Manutenção!$E$21 -> 0 | AC11: =S11 -> 0 | AD11: =SUM(V11:AC11) -> 13104.806 | AE11: =IF($L$2>=1,AD11/$A$5,0) -> 0 | AF11: ='Linha 4 Zn Alc. Manual'!P15 -> 0 | AG11: ='Resumo M.O'!F5 -> 3961.4925 | AH11: ='Resumo M.O'!$F$13 -> 9143.3131 | AI11: ='Resumo Custos Variáveis'!$H$21 -> 0 | AJ11: ='Outros Custos'!$F$31 -> 0 | AK11: =Transporte!$F$20 -> 0 | AL11: =Manutenção!$F$21 -> 0 | AM11: =AC11 -> 0 | AN11: =SUM(AF11:AM11) -> 13104.806 | AO11: =IF(L2>=1,AN11/$A$5,0) -> 0 | AP11: ='Linha 4 Zn Alc. Manual'!S15 -> 0 | AQ11: ='Resumo M.O'!G5 -> 3961.4925 | AR11: ='Resumo M.O'!$G$13 -> 9143.3131 | AS11: ='Resumo Custos Variáveis'!$I$21 -> 0 | AT11: ='Outros Custos'!$G$31 -> 0 | AU11: =Transporte!$G$20 -> 0 | AV11: =Manutenção!$G$21 -> 0 | AW11: =AM11 -> 0 | AX11: =SUM(AP11:AW11) -> 13104.806 | AY11: =IF(L2>=1,AX11/$A$5,0) -> 0 | AZ11: ='Linha 4 Zn Alc. Manual'!V15 -> 0 | BA11: ='Resumo M.O'!H5 -> 3961.4925 | BB11: ='Resumo M.O'!$H$13 -> 9143.3131 | BC11: ='Resumo Custos Variáveis'!$J$21 -> 0 | BD11: ='Outros Custos'!$H$31 -> 0 | BE11: =Transporte!$H$20 -> 0 | BF11: =Manutenção!$H$21 -> 0 | BG11: =AW11 -> 0 | BH11: =SUM(AZ11:BG11) -> 13104.806 | BI11: =IF(L2>=1,BH11/$A$5,0) -> 0 | BJ11: ='Linha 4 Zn Alc. Manual'!Y15 -> 0 | BK11: ='Resumo M.O'!I5 -> 3961.4925 | BL11: ='Resumo M.O'!$I$13 -> 9143.3131 | BM11: ='Resumo Custos Variáveis'!$K$21 -> 0 | BN11: ='Outros Custos'!$I$31 -> 0 | BO11: =Transporte!$I$20 -> 0 | BP11: =Manutenção!$I$21 -> 0 | BQ11: =BG11 -> 0 | BR11: =SUM(BJ11:BQ11) -> 13104.806 | BS11: =IF(L2>=1,BR11/$A$5,0) -> 0 | BT11: ='Linha 4 Zn Alc. Manual'!AB15 -> 0 | BU11: ='Resumo M.O'!J5 -> 3961.4925 | BV11: ='Resumo M.O'!$J$13 -> 9143.3131 | BW11: ='Resumo Custos Variáveis'!$L$21 -> 0 | BX11: ='Outros Custos'!$J$31 -> 0 | BY11: =Transporte!$J$20 -> 0 | BZ11: =Manutenção!$J$21 -> 0 | CA11: =BQ11 -> 0 | CB11: =SUM(BT11:CA11) -> 13104.806 | CC11: =IF(L2>=1,CB11/$A$5,0) -> 0 | CD11: ='Linha 4 Zn Alc. Manual'!AE15 -> 0 | CE11: ='Resumo M.O'!K5 -> 3961.4925 | CF11: ='Resumo M.O'!$K$13 -> 9143.3131 | CG11: ='Resumo Custos Variáveis'!$M$21 -> 4328.5714 | CH11: ='Outros Custos'!$K$31 -> 2140 | CI11: =Transporte!$K$20 -> 0 | CJ11: =Manutenção!$K$21 -> 10000 | CK11: =CA11 -> 0 | CL11: =SUM(CD11:CK11) -> 29573.377 | CM11: =IF(L2>=1,CL11/$A$5,0) -> 0 | CN11: ='Linha 4 Zn Alc. Manual'!AH15 -> 0 | CO11: ='Resumo M.O'!L5 -> 3961.4925 | CP11: ='Resumo M.O'!$L$13 -> 9143.3131 | CQ11: ='Resumo Custos Variáveis'!$N$21 -> 0 | CR11: ='Outros Custos'!$L$31 -> 0 | CS11: =Transporte!$L$20 -> 0 | CT11: =Manutenção!$L$21 -> 10000 | CU11: =CK11 -> 0 | CV11: =SUM(CN11:CU11) -> 23104.806 | CW11: =IF(L2>=1,CV11/$A$5,0) -> 0 | CX11: ='Linha 4 Zn Alc. Manual'!AK15 -> 0 | CY11: ='Resumo M.O'!M5 -> 3961.4925 | CZ11: ='Resumo M.O'!$M$13 -> 9143.3131 | DA11: ='Resumo Custos Variáveis'!$O$21 -> 0 | DB11: ='Outros Custos'!$M$31 -> 0 | DC11: =Transporte!$M$20 -> 0 | DD11: =Manutenção!$M$21 -> 10000 | DE11: =CU11 -> 0 | DF11: =SUM(CX11:DE11) -> 23104.806 | DG11: =IF(L2>=1,DF11/$A$5,0) -> 0 | DH11: ='Linha 4 Zn Alc. Manual'!AN15 -> 0 | DI11: ='Resumo M.O'!N5 -> 3961.4925 | DJ11: ='Resumo M.O'!$N$13 -> 9143.3131 | DK11: ='Resumo Custos Variáveis'!$P$21 -> 0 | DL11: ='Outros Custos'!$N$31 -> 0 | DM11: =Transporte!$N$20 -> 0 | DN11: =Manutenção!$N$21 -> 10000 | DO11: =DE11 -> 0 | DP11: =SUM(DH11:DO11) -> 23104.806 | DQ11: =IF(L2>=1,DP11/$A$5,0) -> 0 | DS11: =K11 -> 0 | DT11: =U11 -> 0 | DU11: =AE11 -> 0 | DV11: =AO11 -> 0 | DW11: =AY11 -> 0 | DX11: =BI11 -> 0 | DY11: =BS11 -> 0 | DZ11: =CC11 -> 0 | EA11: =CM11 -> 0 | EB11: =CW11 -> 0 | EC11: =DG11 -> 0 | ED11: =DQ11 -> 0 | EF11: =B11/$A$5 -> 0 | EG11: =L11/$A$5 -> 0 | EH11: =V11/$A$5 -> 0 | EI11: =AF11/$A$5 -> 0 | EJ11: =AP11/$A$5 -> 0 | EK11: =AZ11/$A$5 -> 0 | EL11: =BJ11/$A$5 -> 0 | EM11: =BT11/$A$5 -> 0 | EN11: =CD11/$A$5 -> 0 | EO11: =CN11/$A$5 -> 0 | EP11: =CX11/$A$5 -> 0 | EQ11: =DH11/$A$5 -> 0
A12: Linha 5 Zn Alc.Semi Aut | B12: ='Linha 5 Zn Alc. Semi Aut.'!G15 -> 0 | C12: ='Resumo M.O'!C6 -> 7491.4369 | D12: ='Resumo M.O'!$C$13 -> 9143.3131 | E12: ='Resumo Custos Variáveis'!$E$21 -> 0 | F12: ='Outros Custos'!$C$31 -> 0 | G12: =Transporte!$C$20 -> 0 | H12: =Manutenção!$C$21 -> 0 | I12: =Investimentos!G32 -> 0 | J12: =SUM(B12:I12) -> 16634.75 | K12: =IF($L$2>=1,J12/$A$5,0) -> 0 | L12: ='Linha 5 Zn Alc. Semi Aut.'!J15 -> 0 | M12: ='Resumo M.O'!D6 -> 7491.4369 | N12: ='Resumo M.O'!$D$13 -> 9143.3131 | O12: ='Resumo Custos Variáveis'!$F$21 -> 0 | P12: ='Outros Custos'!$D$31 -> 0 | Q12: =Transporte!$D$20 -> 0 | R12: =Manutenção!$D$21 -> 0 | S12: =I12 -> 0 | T12: =SUM(L12:S12) -> 16634.75 | U12: =IF($L$2>=1,T12/$A$5,0) -> 0 | V12: ='Linha 5 Zn Alc. Semi Aut.'!M15 -> 0 | W12: ='Resumo M.O'!E6 -> 7491.4369 | X12: ='Resumo M.O'!$E$13 -> 9143.3131 | Y12: ='Resumo Custos Variáveis'!$G$21 -> 0 | Z12: ='Outros Custos'!$E$31 -> 0 | AA12: =Transporte!$E$20 -> 0 | AB12: =Manutenção!$E$21 -> 0 | AC12: =S12 -> 0 | AD12: =SUM(V12:AC12) -> 16634.75 | AE12: =IF($L$2>=1,AD12/$A$5,0) -> 0 | AF12: ='Linha 5 Zn Alc. Semi Aut.'!P15 -> 0 | AG12: ='Resumo M.O'!F6 -> 7491.4369 | AH12: ='Resumo M.O'!$F$13 -> 9143.3131 | AI12: ='Resumo Custos Variáveis'!$H$21 -> 0 | AJ12: ='Outros Custos'!$F$31 -> 0 | AK12: =Transporte!$F$20 -> 0 | AL12: =Manutenção!$F$21 -> 0 | AM12: =AC12 -> 0 | AN12: =SUM(AF12:AM12) -> 16634.75 | AO12: =IF(L2>=1,AN12/$A$5,0) -> 0 | AP12: ='Linha 5 Zn Alc. Semi Aut.'!S15 -> 0 | AQ12: ='Resumo M.O'!G6 -> 7491.4369 | AR12: ='Resumo M.O'!$G$13 -> 9143.3131 | AS12: ='Resumo Custos Variáveis'!$I$21 -> 0 | AT12: ='Outros Custos'!$G$31 -> 0 | AU12: =Transporte!$G$20 -> 0 | AV12: =Manutenção!$G$21 -> 0 | AW12: =AM12 -> 0 | AX12: =SUM(AP12:AW12) -> 16634.75 | AY12: =IF(L2>=1,AX12/$A$5,0) -> 0 | AZ12: ='Linha 5 Zn Alc. Semi Aut.'!V15 -> 0 | BA12: ='Resumo M.O'!H6 -> 7491.4369 | BB12: ='Resumo M.O'!$H$13 -> 9143.3131 | BC12: ='Resumo Custos Variáveis'!$J$21 -> 0 | BD12: ='Outros Custos'!$H$31 -> 0 | BE12: =Transporte!$H$20 -> 0 | BF12: =Manutenção!$H$21 -> 0 | BG12: =AW12 -> 0 | BH12: =SUM(AZ12:BG12) -> 16634.75 | BI12: =IF(L$2>=1,BH12/$A$5,0) -> 0 | BJ12: ='Linha 5 Zn Alc. Semi Aut.'!Y15 -> 0 | BK12: ='Resumo M.O'!I6 -> 7491.4369 | BL12: ='Resumo M.O'!$I$13 -> 9143.3131 | BM12: ='Resumo Custos Variáveis'!$K$21 -> 0 | BN12: ='Outros Custos'!$I$31 -> 0 | BO12: =Transporte!$I$20 -> 0 | BP12: =Manutenção!$I$21 -> 0 | BQ12: =BG12 -> 0 | BR12: =SUM(BJ12:BQ12) -> 16634.75 | BS12: =IF(L$2>=1,BR12/$A$5,0) -> 0 | BT12: ='Linha 5 Zn Alc. Semi Aut.'!AB15 -> 0 | BU12: ='Resumo M.O'!J6 -> 7491.4369 | BV12: ='Resumo M.O'!$J$13 -> 9143.3131 | BW12: ='Resumo Custos Variáveis'!$L$21 -> 0 | BX12: ='Outros Custos'!$J$31 -> 0 | BY12: =Transporte!$J$20 -> 0 | BZ12: =Manutenção!$J$21 -> 0 | CA12: =BQ12 -> 0 | CB12: =SUM(BT12:CA12) -> 16634.75 | CC12: =IF(L$2>=1,CB12/$A$5,0) -> 0 | CD12: ='Linha 5 Zn Alc. Semi Aut.'!AE15 -> 0 | CE12: ='Resumo M.O'!K6 -> 3126.8886 | CF12: ='Resumo M.O'!$K$13 -> 9143.3131 | CG12: ='Resumo Custos Variáveis'!$M$21 -> 4328.5714 | CH12: ='Outros Custos'!$K$31 -> 2140 | CI12: =Transporte!$K$20 -> 0 | CJ12: =Manutenção!$K$21 -> 10000 | CK12: =CA12 -> 0 | CL12: =SUM(CD12:CK12) -> 28738.773 | CM12: =IF(L2>=1,CL12/$A$5,0) -> 0 | CN12: ='Linha 5 Zn Alc. Semi Aut.'!AH15 -> 0 | CO12: ='Resumo M.O'!L6 -> 3126.8886 | CP12: ='Resumo M.O'!$L$13 -> 9143.3131 | CQ12: ='Resumo Custos Variáveis'!$N$21 -> 0 | CR12: ='Outros Custos'!$L$31 -> 0 | CS12: =Transporte!$L$20 -> 0 | CT12: =Manutenção!$L$21 -> 10000 | CU12: =CK12 -> 0 | CV12: =SUM(CN12:CU12) -> 22270.202 | CW12: =IF(L$2>=1,CV12/$A$5,0) -> 0 | CX12: ='Linha 5 Zn Alc. Semi Aut.'!AK15 -> 0 | CY12: ='Resumo M.O'!M6 -> 3126.8886 | CZ12: ='Resumo M.O'!$M$13 -> 9143.3131 | DA12: ='Resumo Custos Variáveis'!$O$21 -> 0 | DB12: ='Outros Custos'!$M$31 -> 0 | DC12: =Transporte!$M$20 -> 0 | DD12: =Manutenção!$M$21 -> 10000 | DE12: =CU12 -> 0 | DF12: =SUM(CX12:DE12) -> 22270.202 | DG12: =IF(L$2>=1,DF12/$A$5,0) -> 0 | DH12: ='Linha 5 Zn Alc. Semi Aut.'!AN15 -> 0 | DI12: ='Resumo M.O'!N6 -> 3126.8886 | DJ12: ='Resumo M.O'!$N$13 -> 9143.3131 | DK12: ='Resumo Custos Variáveis'!$P$21 -> 0 | DL12: ='Outros Custos'!$N$31 -> 0 | DM12: =Transporte!$N$20 -> 0 | DN12: =Manutenção!$N$21 -> 10000 | DO12: =DE12 -> 0 | DP12: =SUM(DH12:DO12) -> 22270.202 | DQ12: =IF(L$2>=1,DP12/$A$5,0) -> 0 | DS12: =K12 -> 0 | DT12: =U12 -> 0 | DU12: =AE12 -> 0 | DV12: =AO12 -> 0 | DW12: =AY12 -> 0 | DX12: =BI12 -> 0 | DY12: =BS12 -> 0 | DZ12: =CC12 -> 0 | EA12: =CM12 -> 0 | EB12: =CW12 -> 0 | EC12: =DG12 -> 0 | ED12: =DQ12 -> 0 | EF12: =B12/$A$5 -> 0 | EG12: =L12/$A$5 -> 0 | EH12: =V12/$A$5 -> 0 | EI12: =AF12/$A$5 -> 0 | EJ12: =AP12/$A$5 -> 0 | EK12: =AZ12/$A$5 -> 0 | EL12: =BJ12/$A$5 -> 0 | EM12: =BT12/$A$5 -> 0 | EN12: =CD12/$A$5 -> 0 | EO12: =CN12/$A$5 -> 0 | EP12: =CX12/$A$5 -> 0 | EQ12: =DH12/$A$5 -> 0
A13: Linha 6 ZnNí Alc.Semi Aut | B13: ='Linha 6 ZnNí Semi Aut.'!G16 -> 0 | C13: ='Resumo M.O'!C7 -> 6872.2222 | D13: ='Resumo M.O'!$C$13 -> 9143.3131 | E13: ='Resumo Custos Variáveis'!$E$21 -> 0 | F13: ='Outros Custos'!$C$31 -> 0 | G13: =Transporte!$C$20 -> 0 | H13: =Manutenção!$C$21 -> 0 | I13: =Investimentos!G37 -> 0 | J13: =SUM(B13:I13) -> 16015.535 | K13: =IF($L$2>=1,J13/$A$5,0) -> 0 | L13: ='Linha 6 ZnNí Semi Aut.'!J16 -> 0 | M13: ='Resumo M.O'!D7 -> 6872.2222 | N13: ='Resumo M.O'!$D$13 -> 9143.3131 | O13: ='Resumo Custos Variáveis'!$F$21 -> 0 | P13: ='Outros Custos'!$D$31 -> 0 | Q13: =Transporte!$D$20 -> 0 | R13: =Manutenção!$D$21 -> 0 | S13: =I13 -> 0 | T13: =SUM(L13:S13) -> 16015.535 | U13: =IF($L$2>=1,T13/$A$5,0) -> 0 | V13: ='Linha 6 ZnNí Semi Aut.'!M16 -> 0 | W13: ='Resumo M.O'!E7 -> 6872.2222 | X13: ='Resumo M.O'!$E$13 -> 9143.3131 | Y13: ='Resumo Custos Variáveis'!$G$21 -> 0 | Z13: ='Outros Custos'!$E$31 -> 0 | AA13: =Transporte!$E$20 -> 0 | AB13: =Manutenção!$E$21 -> 0 | AC13: =S13 -> 0 | AD13: =SUM(V13:AC13) -> 16015.535 | AE13: =IF($L$2>=1,AD13/$A$5,0) -> 0 | AF13: ='Linha 6 ZnNí Semi Aut.'!P16 -> 0 | AG13: ='Resumo M.O'!F7 -> 6872.2222 | AH13: ='Resumo M.O'!$F$13 -> 9143.3131 | AI13: ='Resumo Custos Variáveis'!$H$21 -> 0 | AJ13: ='Outros Custos'!$F$31 -> 0 | AK13: =Transporte!$F$20 -> 0 | AL13: =Manutenção!$F$21 -> 0 | AM13: =AC13 -> 0 | AN13: =SUM(AF13:AM13) -> 16015.535 | AO13: =IF(L2>=1,AN13/$A$5,0) -> 0 | AP13: ='Linha 6 ZnNí Semi Aut.'!S16 -> 0 | AQ13: ='Resumo M.O'!G7 -> 6872.2222 | AR13: ='Resumo M.O'!$G$13 -> 9143.3131 | AS13: ='Resumo Custos Variáveis'!$I$21 -> 0 | AT13: ='Outros Custos'!$G$31 -> 0 | AU13: =Transporte!$G$20 -> 0 | AV13: =Manutenção!$G$21 -> 0 | AW13: =AM13 -> 0 | AX13: =SUM(AP13:AW13) -> 16015.535 | AY13: =IF(L2>=1,AX13/$A$5,0) -> 0 | AZ13: ='Linha 6 ZnNí Semi Aut.'!V16 -> 0 | BA13: ='Resumo M.O'!H7 -> 6872.2222 | BB13: ='Resumo M.O'!$H$13 -> 9143.3131 | BC13: ='Resumo Custos Variáveis'!$J$21 -> 0 | BD13: ='Outros Custos'!$H$31 -> 0 | BE13: =Transporte!$H$20 -> 0 | BF13: =Manutenção!$H$21 -> 0 | BG13: =AW13 -> 0 | BH13: =SUM(AZ13:BG13) -> 16015.535 | BI13: =IF(L$2>=1,BH13/$A$5,0) -> 0 | BJ13: ='Linha 6 ZnNí Semi Aut.'!Y16 -> 0 | BK13: ='Resumo M.O'!I7 -> 6872.2222 | BL13: ='Resumo M.O'!$I$13 -> 9143.3131 | BM13: ='Resumo Custos Variáveis'!$K$21 -> 0 | BN13: ='Outros Custos'!$I$31 -> 0 | BO13: =Transporte!$I$20 -> 0 | BP13: =Manutenção!$I$21 -> 0 | BQ13: =BG13 -> 0 | BR13: =SUM(BJ13:BQ13) -> 16015.535 | BS13: =IF(L$2>=1,BR13/$A$5,0) -> 0 | BT13: ='Linha 6 ZnNí Semi Aut.'!AB16 -> 0 | BU13: ='Resumo M.O'!J7 -> 6872.2222 | BV13: ='Resumo M.O'!$J$13 -> 9143.3131 | BW13: ='Resumo Custos Variáveis'!$L$21 -> 0 | BX13: ='Outros Custos'!$J$31 -> 0 | BY13: =Transporte!$J$20 -> 0 | BZ13: =Manutenção!$J$21 -> 0 | CA13: =BQ13 -> 0 | CB13: =SUM(BT13:CA13) -> 16015.535 | CC13: =IF(L$2>=1,CB13/$A$5,0) -> 0 | CD13: ='Linha 6 ZnNí Semi Aut.'!AE16 -> 40000 | CE13: ='Resumo M.O'!K7 -> 6047.5556 | CF13: ='Resumo M.O'!$K$13 -> 9143.3131 | CG13: ='Resumo Custos Variáveis'!$M$21 -> 4328.5714 | CH13: ='Outros Custos'!$K$31 -> 2140 | CI13: =Transporte!$K$20 -> 0 | CJ13: =Manutenção!$K$21 -> 10000 | CK13: =CA13 -> 0 | CL13: =SUM(CD13:CK13) -> 71659.44 | CM13: =IF(L2>=1,CL13/$A$5,0) -> 0 | CN13: ='Linha 6 ZnNí Semi Aut.'!AH16 -> 0 | CO13: ='Resumo M.O'!L7 -> 6047.5556 | CP13: ='Resumo M.O'!$L$13 -> 9143.3131 | CQ13: ='Resumo Custos Variáveis'!$N$21 -> 0 | CR13: ='Outros Custos'!$L$31 -> 0 | CS13: =Transporte!$L$20 -> 0 | CT13: =Manutenção!$L$21 -> 10000 | CU13: =CK13 -> 0 | CV13: =SUM(CN13:CU13) -> 25190.869 | CW13: =IF(L$2>=1,CV13/$A$5,0) -> 0 | CX13: ='Linha 6 ZnNí Semi Aut.'!AK16 -> 0 | CY13: ='Resumo M.O'!M7 -> 6047.5556 | CZ13: ='Resumo M.O'!$M$13 -> 9143.3131 | DA13: ='Resumo Custos Variáveis'!$O$21 -> 0 | DB13: ='Outros Custos'!$M$31 -> 0 | DC13: =Transporte!$M$20 -> 0 | DD13: =Manutenção!$M$21 -> 10000 | DE13: =CU13 -> 0 | DF13: =SUM(CX13:DE13) -> 25190.869 | DG13: =IF(L$2>=1,DF13/$A$5,0) -> 0 | DH13: ='Linha 6 ZnNí Semi Aut.'!AN16 -> 0 | DI13: ='Resumo M.O'!N7 -> 6047.5556 | DJ13: ='Resumo M.O'!$N$13 -> 9143.3131 | DK13: ='Resumo Custos Variáveis'!$P$21 -> 0 | DL13: ='Outros Custos'!$N$31 -> 0 | DM13: =Transporte!$N$20 -> 0 | DN13: =Manutenção!$N$21 -> 10000 | DO13: =DE13 -> 0 | DP13: =SUM(DH13:DO13) -> 25190.869 | DQ13: =IF(L$2>=1,DP13/$A$5,0) -> 0 | DS13: =K13 -> 0 | DT13: =U13 -> 0 | DU13: =AE13 -> 0 | DV13: =AO13 -> 0 | DW13: =AY13 -> 0 | DX13: =BI13 -> 0 | DY13: =BS13 -> 0 | DZ13: =CC13 -> 0 | EA13: =CM13 -> 0 | EB13: =CW13 -> 0 | EC13: =DG13 -> 0 | ED13: =DQ13 -> 0 | EF13: =B13/$A$5 -> 0 | EG13: =L13/$A$5 -> 0 | EH13: =V13/$A$5 -> 0 | EI13: =AF13/$A$5 -> 0 | EJ13: =AP13/$A$5 -> 0 | EK13: =AZ13/$A$5 -> 0 | EL13: =BJ13/$A$5 -> 0 | EM13: =BT13/$A$5 -> 0 | EN13: =CD13/$A$5 -> 181.81818 | EO13: =CN13/$A$5 -> 0 | EP13: =CX13/$A$5 -> 0 | EQ13: =DH13/$A$5 -> 0
A14: Linha 9 Pré-Trat. Fosfato Aut. | B14: ='Linha 9 Pré Trat. Fosfato Aut.'!G14 -> 0 | C14: ='Resumo M.O'!C8 -> 3023.7778 | D14: ='Resumo M.O'!$C$13 -> 9143.3131 | E14: ='Resumo Custos Variáveis'!$E$21 -> 0 | F14: ='Outros Custos'!$C$31 -> 0 | G14: =Transporte!$C$20 -> 0 | H14: =Manutenção!$C$21 -> 0 | I14: =Investimentos!G42 -> 0 | J14: =SUM(B14:I14) -> 12167.091 | K14: =IF($L$2>=1,J14/$A$5,0) -> 0 | L14: ='Linha 9 Pré Trat. Fosfato Aut.'!J14 -> 0 | M14: ='Resumo M.O'!D8 -> 3023.7778 | N14: ='Resumo M.O'!$D$13 -> 9143.3131 | O14: ='Resumo Custos Variáveis'!$F$21 -> 0 | P14: ='Outros Custos'!$D$31 -> 0 | Q14: =Transporte!$D$20 -> 0 | R14: =Manutenção!$D$21 -> 0 | S14: =I14 -> 0 | T14: =SUM(L14:S14) -> 12167.091 | U14: =IF($L$2>=1,T14/$A$5,0) -> 0 | V14: ='Linha 9 Pré Trat. Fosfato Aut.'!M14 -> 0 | W14: ='Resumo M.O'!E8 -> 3023.7778 | X14: ='Resumo M.O'!$E$13 -> 9143.3131 | Y14: ='Resumo Custos Variáveis'!$G$21 -> 0 | Z14: ='Outros Custos'!$E$31 -> 0 | AA14: =Transporte!$E$20 -> 0 | AB14: =Manutenção!$E$21 -> 0 | AC14: =S14 -> 0 | AD14: =SUM(V14:AC14) -> 12167.091 | AE14: =IF($L$2>=1,AD14/$A$5,0) -> 0 | AF14: ='Linha 9 Pré Trat. Fosfato Aut.'!P14 -> 0 | AG14: ='Resumo M.O'!F8 -> 3023.7778 | AH14: ='Resumo M.O'!$F$13 -> 9143.3131 | AI14: ='Resumo Custos Variáveis'!$H$21 -> 0 | AJ14: ='Outros Custos'!$F$31 -> 0 | AK14: =Transporte!$F$20 -> 0 | AL14: =Manutenção!$F$21 -> 0 | AM14: =AC14 -> 0 | AN14: =SUM(AF14:AM14) -> 12167.091 | AO14: =IF(L2>=1,AN14/$A$5,0) -> 0 | AP14: ='Linha 9 Pré Trat. Fosfato Aut.'!S14 -> 0 | AQ14: ='Resumo M.O'!G8 -> 3023.7778 | AR14: ='Resumo M.O'!$G$13 -> 9143.3131 | AS14: ='Resumo Custos Variáveis'!$I$21 -> 0 | AT14: ='Outros Custos'!$G$31 -> 0 | AU14: =Transporte!$G$20 -> 0 | AV14: =Manutenção!$G$21 -> 0 | AW14: =AM14 -> 0 | AX14: =SUM(AP14:AW14) -> 12167.091 | AY14: =IF(L2>=1,AX14/$A$5,0) -> 0 | AZ14: ='Linha 9 Pré Trat. Fosfato Aut.'!V14 -> 0 | BA14: ='Resumo M.O'!H8 -> 3023.7778 | BB14: ='Resumo M.O'!$H$13 -> 9143.3131 | BC14: ='Resumo Custos Variáveis'!$J$21 -> 0 | BD14: ='Outros Custos'!$H$31 -> 0 | BE14: =Transporte!$H$20 -> 0 | BF14: =Manutenção!$H$21 -> 0 | BG14: =AW14 -> 0 | BH14: =SUM(AZ14:BG14) -> 12167.091 | BI14: =IF(L$2>=1,BH14/$A$5,0) -> 0 | BJ14: ='Linha 9 Pré Trat. Fosfato Aut.'!Y14 -> 0 | BK14: ='Resumo M.O'!I8 -> 3023.7778 | BL14: ='Resumo M.O'!$I$13 -> 9143.3131 | BM14: ='Resumo Custos Variáveis'!$K$21 -> 0 | BN14: ='Outros Custos'!$I$31 -> 0 | BO14: =Transporte!$I$20 -> 0 | BP14: =Manutenção!$I$21 -> 0 | BQ14: =BG14 -> 0 | BR14: =SUM(BJ14:BQ14) -> 12167.091 | BS14: =IF(L$2>=1,BR14/$A$5,0) -> 0 | BT14: ='Linha 9 Pré Trat. Fosfato Aut.'!AB14 -> 0 | BU14: ='Resumo M.O'!J8 -> 3023.7778 | BV14: ='Resumo M.O'!$J$13 -> 9143.3131 | BW14: ='Resumo Custos Variáveis'!$L$21 -> 0 | BX14: ='Outros Custos'!$J$31 -> 0 | BY14: =Transporte!$J$20 -> 0 | BZ14: =Manutenção!$J$21 -> 0 | CA14: =BQ14 -> 0 | CB14: =SUM(BT14:CA14) -> 12167.091 | CC14: =IF(L$2>=1,CB14/$A$5,0) -> 0 | CD14: ='Linha 9 Pré Trat. Fosfato Aut.'!AE14 -> 0 | CE14: ='Resumo M.O'!K8 -> 3023.7778 | CF14: ='Resumo M.O'!$K$13 -> 9143.3131 | CG14: ='Resumo Custos Variáveis'!$M$21 -> 4328.5714 | CH14: ='Outros Custos'!$K$31 -> 2140 | CI14: =Transporte!$K$20 -> 0 | CJ14: =Manutenção!$K$21 -> 10000 | CK14: =CA14 -> 0 | CL14: =SUM(CD14:CK14) -> 28635.662 | CM14: =IF(L2>=1,CL14/$A$5,0) -> 0 | CN14: ='Linha 9 Pré Trat. Fosfato Aut.'!AH14 -> 0 | CO14: ='Resumo M.O'!L8 -> 3023.7778 | CP14: ='Resumo M.O'!$L$13 -> 9143.3131 | CQ14: ='Resumo Custos Variáveis'!$N$21 -> 0 | CR14: ='Outros Custos'!$L$31 -> 0 | CS14: =Transporte!$L$20 -> 0 | CT14: =Manutenção!$L$21 -> 10000 | CU14: =CK14 -> 0 | CV14: =SUM(CN14:CU14) -> 22167.091 | CW14: =IF(L$2>=1,CV14/$A$5,0) -> 0 | CX14: ='Linha 9 Pré Trat. Fosfato Aut.'!AK14 -> 0 | CY14: ='Resumo M.O'!M8 -> 3023.7778 | CZ14: ='Resumo M.O'!$M$13 -> 9143.3131 | DA14: ='Resumo Custos Variáveis'!$O$21 -> 0 | DB14: ='Outros Custos'!$M$31 -> 0 | DC14: =Transporte!$M$20 -> 0 | DD14: =Manutenção!$M$21 -> 10000 | DE14: =CU14 -> 0 | DF14: =SUM(CX14:DE14) -> 22167.091 | DG14: =IF(L$2>=1,DF14/$A$5,0) -> 0 | DH14: ='Linha 9 Pré Trat. Fosfato Aut.'!AN14 -> 0 | DI14: ='Resumo M.O'!N8 -> 3023.7778 | DJ14: ='Resumo M.O'!$N$13 -> 9143.3131 | DK14: ='Resumo Custos Variáveis'!$P$21 -> 0 | DL14: ='Outros Custos'!$N$31 -> 0 | DM14: =Transporte!$N$20 -> 0 | DN14: =Manutenção!$N$21 -> 10000 | DO14: =DE14 -> 0 | DP14: =SUM(DH14:DO14) -> 22167.091 | DQ14: =IF(L$2>=1,DP14/$A$5,0) -> 0 | DS14: =K14 -> 0 | DT14: =U14 -> 0 | DU14: =AE14 -> 0 | DV14: =AO14 -> 0 | DW14: =AY14 -> 0 | DX14: =BI14 -> 0 | DY14: =BS14 -> 0 | DZ14: =CC14 -> 0 | EA14: =CM14 -> 0 | EB14: =CW14 -> 0 | EC14: =DG14 -> 0 | ED14: =DQ14 -> 0 | EF14: =B14/$A$5 -> 0 | EG14: =L14/$A$5 -> 0 | EH14: =V14/$A$5 -> 0 | EI14: =AF14/$A$5 -> 0 | EJ14: =AP14/$A$5 -> 0 | EK14: =AZ14/$A$5 -> 0 | EL14: =BJ14/$A$5 -> 0 | EM14: =BT14/$A$5 -> 0 | EN14: =CD14/$A$5 -> 0 | EO14: =CN14/$A$5 -> 0 | EP14: =CX14/$A$5 -> 0 | EQ14: =DH14/$A$5 -> 0
A15: E.T.E | B15: 0 | C15: ='Resumo M.O'!C9 -> 0 | D15: 0 | E15: ='Resumo Custos Variáveis'!$E$21 -> 0 | F15: ='Outros Custos'!$C$31 -> 0 | G15: =Transporte!$C$20 -> 0 | H15: =Manutenção!$C$21 -> 0 | I15: 0 | J15: =SUM(B15:I15) -> 0 | K15: =IF($L$2>=1,J15/$A$5,0) -> 0 | L15: 0 | M15: ='Resumo M.O'!D9 -> 0 | N15: 0 | O15: ='Resumo Custos Variáveis'!$F$21 -> 0 | P15: ='Outros Custos'!$D$31 -> 0 | Q15: =Transporte!$D$20 -> 0 | R15: =Manutenção!$D$21 -> 0 | S15: =I15 -> 0 | T15: =SUM(L15:S15) -> 0 | U15: =IF($L$2>=1,T15/$A$5,0) -> 0 | V15: 0 | W15: ='Resumo M.O'!E9 -> 0 | X15: 0 | Y15: ='Resumo Custos Variáveis'!$G$21 -> 0 | Z15: ='Outros Custos'!$E$31 -> 0 | AA15: =Transporte!$E$20 -> 0 | AB15: =Manutenção!$E$21 -> 0 | AC15: =S15 -> 0 | AD15: =SUM(V15:AC15) -> 0 | AE15: =IF($L$2>=1,AD15/$A$5,0) -> 0 | AF15: 0 | AG15: ='Resumo M.O'!F9 -> 0 | AH15: 0 | AI15: ='Resumo Custos Variáveis'!$H$21 -> 0 | AJ15: ='Outros Custos'!$F$31 -> 0 | AK15: =Transporte!$F$20 -> 0 | AL15: =Manutenção!$F$21 -> 0 | AM15: =AC15 -> 0 | AN15: =SUM(AF15:AM15) -> 0 | AO15: =IF(L2>=1,AN15/$A$5,0) -> 0 | AP15: 0 | AQ15: ='Resumo M.O'!G9 -> 0 | AR15: 0 | AS15: ='Resumo Custos Variáveis'!$I$21 -> 0 | AT15: ='Outros Custos'!$G$31 -> 0 | AU15: =Transporte!$G$20 -> 0 | AV15: =Manutenção!$G$21 -> 0 | AW15: =AM15 -> 0 | AX15: =SUM(AP15:AW15) -> 0 | AY15: =IF(L2>=1,AX15/$A$5,0) -> 0 | AZ15: 0 | BA15: ='Resumo M.O'!H9 -> 0 | BB15: 0 | BC15: ='Resumo Custos Variáveis'!$J$21 -> 0 | BD15: ='Outros Custos'!$H$31 -> 0 | BE15: =Transporte!$H$20 -> 0 | BF15: =Manutenção!$H$21 -> 0 | BG15: =AW15 -> 0 | BH15: =SUM(AZ15:BG15) -> 0 | BI15: =IF(L$2>=1,BH15/$A$5,0) -> 0 | BJ15: 0 | BK15: ='Resumo M.O'!I9 -> 0 | BL15: 0 | BM15: ='Resumo Custos Variáveis'!$K$21 -> 0 | BN15: ='Outros Custos'!$I$31 -> 0 | BO15: =Transporte!$I$20 -> 0 | BP15: =Manutenção!$I$21 -> 0 | BQ15: =BG15 -> 0 | BR15: =SUM(BJ15:BQ15) -> 0 | BS15: =IF(L$2>=1,BR15/$A$5,0) -> 0 | BT15: 0 | BU15: ='Resumo M.O'!J9 -> 0 | BV15: 0 | BW15: ='Resumo Custos Variáveis'!$L$21 -> 0 | BX15: ='Outros Custos'!$J$31 -> 0 | BY15: =Transporte!$J$20 -> 0 | BZ15: =Manutenção!$J$21 -> 0 | CA15: =BQ15 -> 0 | CB15: =SUM(BT15:CA15) -> 0 | CC15: =IF(L$2>=1,CB15/$A$5,0) -> 0 | CD15: 0 | CE15: ='Resumo M.O'!K9 -> 0 | CF15: 0 | CG15: 0 | CH15: 0 | CI15: =Transporte!$K$20 -> 0 | CJ15: 0 | CK15: =CA15 -> 0 | CL15: =SUM(CD15:CK15) -> 0 | CM15: =IF(L4>=1,CL15/$A$5,0) -> 0 | CN15: 0 | CO15: ='Resumo M.O'!L9 -> 0 | CP15: 0 | CQ15: ='Resumo Custos Variáveis'!$N$21 -> 0 | CR15: ='Outros Custos'!$L$31 -> 0 | CS15: =Transporte!$L$20 -> 0 | CT15: 0 | CU15: =CK15 -> 0 | CV15: =SUM(CN15:CU15) -> 0 | CW15: =IF(L$2>=1,CV15/$A$5,0) -> 0 | CX15: 0 | CY15: ='Resumo M.O'!M9 -> 0 | CZ15: 0 | DA15: ='Resumo Custos Variáveis'!$O$21 -> 0 | DB15: ='Outros Custos'!$M$31 -> 0 | DC15: =Transporte!$M$20 -> 0 | DD15: 0 | DE15: =CU15 -> 0 | DF15: =SUM(CX15:DE15) -> 0 | DG15: =IF(L$2>=1,DF15/$A$5,0) -> 0 | DH15: 0 | DI15: ='Resumo M.O'!N9 -> 0 | DJ15: 0 | DK15: ='Resumo Custos Variáveis'!$P$21 -> 0 | DL15: ='Outros Custos'!$N$31 -> 0 | DM15: =Transporte!$N$20 -> 0 | DN15: 0 | DO15: =DE15 -> 0 | DP15: =SUM(DH15:DO15) -> 0 | DQ15: =IF(L$2>=1,DP15/$A$5,0) -> 0 | DS15: =K15 -> 0 | DT15: =U15 -> 0 | DU15: =AE15 -> 0 | DV15: =AO15 -> 0 | DW15: =AY15 -> 0 | DX15: =BI15 -> 0 | DY15: =BS15 -> 0 | DZ15: =CC15 -> 0 | EA15: =CM15 -> 0 | EB15: =CW15 -> 0 | EC15: =DG15 -> 0 | ED15: =DQ15 -> 0 | EF15: =B15/$A$5 -> 0 | EG15: =L15/$A$5 -> 0 | EH15: =V15/$A$5 -> 0 | EI15: =AF15/$A$5 -> 0 | EJ15: =AP15/$A$5 -> 0 | EK15: =AZ15/$A$5 -> 0 | EL15: =BJ15/$A$5 -> 0 | EM15: =BT15/$A$5 -> 0 | EN15: =CD15/$A$5 -> 0 | EO15: =CN15/$A$5 -> 0 | EP15: =CX15/$A$5 -> 0 | EQ15: =DH15/$A$5 -> 0

Sheet Peças por Hora Galvanoplastia
A2: Menu | C2: Peças por Hora Galvanoplastia
B5: Linha 1 Zn Alcalino Rotativo
B6: Área de 1 peça (dm²) | C6: Peso de 1 peça (Kg) | D6: Kg / Carga | E6: Peças/carga | F6: Area da Carga / Dm² | H6: Peso Especifico | I6: 7.1
B7: 2.3 | C7: 0.7 | D7: 30 | E7: =D7/C7 -> 42.857143 | F7: =(E7*B7)*F9 -> 492.85714 | H7: Equivalente Eletroquimico | I7: 1.2195
B8: Rendimento de corrente (%) | C8: Espessura (mm) | E8: Amperagem | F8: Número de Tambores
B9: 90 | C9: 4 | E9: =E11*F7 -> 246.42857 | F9: 5
B10: Peças por hora | C10: Kg por hora | E10: Densidade de Corrente | F10: Tempo de banho
B11: =(60/F11)*E7*F9 -> 414.06564 | C11: =(60/F11)*D7*F9 -> 289.84595 | E11: 0.5 | F11: =(60*C9*I6)/(I7*E11*B9) -> 31.050977
B13: Linha 2 Zn Alcalino Rotativo
B14: Área de 1 peça (dm²) | C14: Peso de 1 peça (Kg) | D14: Kg/ Carga | E14: Peças por carga | F14: Area da Carga / Dm² | H14: Peso Especifico | I14: 7.1
B15: 2.3 | C15: 0.7 | D15: 30 | E15: =D15/C15 -> 42.857143 | F15: =(B15*E15)*F17 -> 492.85714 | H15: Equivalente Eletroquimico | I15: 1.2195
B16: Rendimento de corrente (%) | C16: Espessura (mm) | E16: Amperagem | F16: Número de Tambores | H16: E Q
B17: 90 | C17: 4 | E17: =E19*F15 -> 246.42857 | F17: 5 | H17: 1.095
B18: Peças por hora | C18: Kg por hora | E18: Densidade de Corrente | F18: Tempo de banho
B19: =(60/F19)*(E15*F17) -> 414.06564 | C19: =(60/F19)*(D15*F17) -> 289.84595 | E19: 0.5 | F19: =(60*C17*I14)/(I15*E19*B17) -> 31.050977
B21: Linha 3 Zn Alcalino Automático
B22: Área de 1 peça (dm²) | C22: Peso de 1 peça (Kg) | D22: Kg/ Carga | E22: Peças por carga | F22: Area da Carga / Dm² | H22: Peso Especifico | I22: 7.1
B23: 2.3 | C23: 0.7 | D23: 30 | E23: =D23/C23 -> 42.857143 | F23: =(E23*B23)*F25 -> 591.42857 | H23: Equivalente Eletroquimico | I23: 1.2195
B24: Rendimento de corrente (%) | C24: Espessura (mm) | E24: Amperagem | F24: Número de Tambores | H24: E Q
B25: 90 | C25: 4 | E25: =E27*F23 -> 591.42857 | F25: 6 | H25: 1.186
B26: Peças por hora | C26: Kg por hora | E26: Densidade de Corrente | F26: Tempo de banho
B27: =(60/F27)*(E23*F25) -> 993.75755 | C27: =(60/F27)*(D23*F25) -> 695.63028 | E27: 1 | F27: =(60*C25*I22)/(I23*E27*B25) -> 15.525489
B29: Linha 4 ZnNí Alcalino Manual
B30: Área de 1 peça (dm²) | C30: Peso de 1 peça (Kg) | D30: Kg / Carga | E30: Peças/carga | F30: Area da Carga / Dm² | H30: Peso Especifico | I30: 7.1
B31: 2.3 | C31: 0.7 | D31: 30 | E31: =D31/C31 -> 42.857143 | F31: =B31*E31*F33 -> 394.28571 | H31: Equivalente Eletroquimico | I31: 1.2195
B32: Rendimento de corrente (%) | C32: Espessura (mm) | E32: Amperagem | F32: Número de Tambores
B33: 90 | C33: 4 | E33: =E35*F31 -> 394.28571 | F33: 4
B34: Peças por hora | C34: Kg por hora | E34: Densidade de Corrente | F34: Tempo de banho
B35: =(60/F35)*E31*F33 -> 662.50503 | C35: =(60/F35)*(D31*F33) -> 463.75352 | E35: 1 | F35: =(60*C33*I30)/(I31*E35*B33) -> 15.525489
B37: Linha 5 Zn Alcalino Semi Parado .
B38: Área de 1 peça (dm²) | C38: Peso de 1 peça (Kg) | D38: Kg / Carga | E38: Peças por carga | F38: Area da Carga / Dm² | H38: Peso Especifico | I38: 7.1
B39: 2.3 | C39: 0.7 | D39: 30 | E39: =D39/C39 -> 42.857143 | F39: =(E39*B39)*F41 -> 690 | H39: Equivalente Eletroquimico | I39: 1.2195
B40: Rendimento de corrente (%) | C40: Espessura (mm) | E40: Amperagem | F40: Número de Gancheira | H40: E Q
B41: 90 | C41: 4 | E41: =E43*F39 -> 690 | F41: 7 | H41: 1.095
B42: Peças por hora | C42: Kg por hora | E42: Densidade de Corrente | F42: Tempo de banho
B43: =(60/F43)*(E39*F41) -> 1159.3838 | C43: =(60/F43)*(D39*F41) -> 811.56866 | E43: 1 | F43: =(60*C41*I38)/(I39*E43*B41) -> 15.525489
B45: Linha 6 ZnNí Aut.
B46: Área de 1 peça (dm²) | C46: Peso de 1 peça (Kg) | D46: Kg / Carga | E46: Peças por carga | F46: Area da Carga / Dm² | H46: Peso Especifico | I46: 7.12
B47: 2.3 | C47: 0.7 | D47: 80 | E47: =D47/C47 -> 114.28571 | F47: =(E47*B47)*F49 -> 2102.8571 | H47: Equivalente Eletroquimico | I47: 1.22
B48: Rendimento de corrente (%) | C48: Espessura (mm) | E48: Amperagem | F48: Número de Gancheira | H48: E Q
...

Sheet Custo Galvanoplastia
A2: Menu | C2: Custo Por Peça Galvanoplastia
G6: Set
B8: Linha 1 | C8: Custo / Peça | D8: Custo/Kilo | E8: Custo/ Peça P.Q | F8: Custo/ Kilo P.Q | H8: Linha 1 | I8: Custo/ Total | K8: Prod. Químico | M8: Linha 1 | N8: % | O8: Peça | P8: Kilo
B9: Zn Alc. Aut | C9: =I9/'Peças por Hora Galvanoplastia'!B11 -> 0 | D9: =I9/'Peças por Hora Galvanoplastia'!C11 -> 0 | E9: =K9/'Peças por Hora Galvanoplastia'!B11 -> 0 | F9: =K9/'Peças por Hora Galvanoplastia'!C11 -> 0 | H9: Zn Alc. Aut | I9: =IF(J9=1,HLOOKUP(G6,'Resumo de Custo'!DS7:ED15,2,0),0) -> 0 | J9: 1 | K9: =IF(J9=1,HLOOKUP(G6,'Resumo de Custo'!EF7:EQ15,2,0),0) -> 0 | M9: Item | N9: 1 | O9: =C20 -> 0 | P9: =D20 -> 0
M10: Imposto Único | N10: 0.15 | O10: =O9*N10 -> 0 | P10: =P9*N10 -> 0
H18: Total | I18: =SUM(I9:I17) -> 0 | K18: =SUM(K9:K17) -> 0 | M18: Custo Liquido | O18: =SUM(O9:O17) -> 0 | P18: =SUM(P9:P17) -> 0
B20: Total | C20: =SUM(C9:C19) -> 0 | D20: =SUM(D9:D19) -> 0 | E20: =SUM(E9:E19) -> 0 | F20: =SUM(F9:F19) -> 0
B23: Linha 2 | C23: Custo / Peça | D23: Custo/Kilo | E23: Custo/ Peça P.Q | F23: Custo/ Kilo P.Q | H23: Linha 2 | I23: Custo/ Total | K23: Prod. Químico | M23: Linha 2 | N23: % | O23: Peça | P23: Kilo
B24: Zn Alc. Aut | C24: =I24/'Peças por Hora Galvanoplastia'!B19 -> 0 | D24: =I24/'Peças por Hora Galvanoplastia'!C19 -> 0 | E24: =K24/'Peças por Hora Galvanoplastia'!B19 -> 0 | F24: =K24/'Peças por Hora Galvanoplastia'!C19 -> 0 | H24: Zn Alc. Aut | I24: =IF(J24=1,HLOOKUP(G6,'Resumo de Custo'!DS7:ED15,3,0),0) -> 0 | J24: 1 | K24: =IF(J24=1,HLOOKUP(G6,'Resumo de Custo'!EF7:EQ15,3,0),0) -> 0 | M24: Item | N24: 1 | O24: =C35 -> 0 | P24: =D35 -> 0
M25: Imposto Único | N25: 0.15 | O25: =O24*N25 -> 0 | P25: =P24*N25 -> 0
H33: Total | I33: =SUM(I24:I32) -> 0 | K33: =SUM(K24:K32) -> 0 | M33: Custo Liquido | O33: =SUM(O24:O32) -> 0 | P33: =SUM(P24:P32) -> 0
B35: Total | C35: =SUM(C24:C34) -> 0 | D35: =SUM(D24:D34) -> 0 | E35: =SUM(E25:E34) -> 0 | F35: =SUM(F24:F34) -> 0
B38: Linha 3 | C38: Custo / Peça | D38: Custo/Kilo | E38: Custo/ Peça P.Q | F38: Custo/ Kilo P.Q | H38: Linha 3 | I38: Custo/ Total | K38: Prod. Químico | M38: Linha 3 | N38: % | O38: Peça | P38: Kilo
B39: Zn Alc. Aut | C39: =I39/'Peças por Hora Galvanoplastia'!B27 -> 0 | D39: =I39/'Peças por Hora Galvanoplastia'!C27 -> 0 | E39: =K39/'Peças por Hora Galvanoplastia'!B27 -> 0 | F39: =K39/'Peças por Hora Galvanoplastia'!C27 -> 0 | H39: Zn Alc. Aut | I39: =IF(J39=1,HLOOKUP(G6,'Resumo de Custo'!DS7:ED15,4,0),0) -> 0 | J39: 1 | K39: =IF(J39,HLOOKUP(G6,'Resumo de Custo'!EF7:EQ15,4,0),0) -> 0 | M39: Item | N39: 1 | O39: =C48 -> 0 | P39: =D48 -> 0
M40: Imposto Único | N40: 0.15 | O40: =O39*N40 -> 0 | P40: =P39*N40 -> 0
H47: Total | I47: =SUM(I39:I46) -> 0 | K47: =SUM(K39:K46) -> 0
B48: Total | C48: =SUM(C39:C47) -> 0 | D48: =SUM(D39:D47) -> 0 | E48: =SUM(E39:E47) -> 0 | F48: =SUM(F39:F47) -> 0 | M48: Custo Liquido | O48: =SUM(O39:O47) -> 0 | P48: =SUM(P39:P47) -> 0
B51: Linha 4 | C51: Custo / Peça | D51: Custo/Kilo | E51: Custo/ Peça P.Q | F51: Custo/ Kilo P.Q | H51: Linha 4 | I51: Custo/ Total | K51: Prod. Químico | M51: Linha 4 | N51: % | O51: Peça | P51: Kilo
B52: Zn Alc. Manual | C52: =I52/'Peças por Hora Galvanoplastia'!B35 -> 0 | D52: =I52/'Peças por Hora Galvanoplastia'!C35 -> 0 | E52: =K52/'Peças por Hora Galvanoplastia'!B35 -> 0 | F52: =K52/'Peças por Hora Galvanoplastia'!C35 -> 0 | H52: Zn Alc. Manual | I52: =IF(J52=1,HLOOKUP(G6,'Resumo de Custo'!DS7:ED15,5,0),0) -> 0 | J52: 1 | K52: =IF(J52=1,HLOOKUP(G6,'Resumo de Custo'!EF7:EQ15,5,0),0) -> 0 | M52: Item | N52: 1 | O52: =C61 -> 0 | P52: =D61 -> 0
M53: Imposto Único | N53: 0.15 | O53: =O52*N53 -> 0 | P53: =P52*N53 -> 0
H60: Total | I60: =SUM(I52:I59) -> 0 | K60: =SUM(K52:K59) -> 0
B61: Total | C61: =SUM(C52:C60) -> 0 | D61: =SUM(D52:D60) -> 0 | E61: =SUM(E52:E60) -> 0 | F61: =SUM(F52:F60) -> 0 | M61: Custo Liquido | O61: =SUM(O52:O60) -> 0 | P61: =SUM(P52:P60) -> 0
B64: Linha 5 | C64: Custo / Peça | D64: Custo/Kilo | E64: Custo/ Peça P.Q | F64: Custo/ Kilo P.Q | H64: Linha 5 | I64: Custo/ Total | K64: Prod. Químico | M64: Linha 5 | N64: % | O64: Peça | P64: Kilo
B65: Zn Alc. Semi Aut. | C65: =I65/'Peças por Hora Galvanoplastia'!B43 -> 0 | D65: =I65/'Peças por Hora Galvanoplastia'!C43 -> 0 | E65: =K65/'Peças por Hora Galvanoplastia'!B43 -> 0 | F65: =K65/'Peças por Hora Galvanoplastia'!C43 -> 0 | H65: Zn Alc. Semi Aut. | I65: =IF(J65=1,HLOOKUP(G6,'Resumo de Custo'!DS7:ED15,6,0),0) -> 0 | J65: 1 | K65: =IF(J65=1,HLOOKUP(G6,'Resumo de Custo'!EF7:EQ15,6,0),0) -> 0 | M65: Item | N65: 1 | O65: =C74 -> 0 | P65: =D74 -> 0
M66: Imposto Único | N66: 0.15 | O66: =O65*N66 -> 0 | P66: =P65*N66 -> 0
H73: Total | I73: =SUM(I65:I72) -> 0 | K73: =SUM(K65:K72) -> 0
B74: Total | C74: =SUM(C65:C73) -> 0 | D74: =SUM(D65:D73) -> 0 | E74: =SUM(E65:E73) -> 0 | F74: =SUM(F65:F73) -> 0 | M74: Custo Liquido | O74: =SUM(O65:O73) -> 0 | P74: =SUM(P65:P73) -> 0
B77: Linha 6 | C77: Custo / Peça | D77: Custo/Kilo | E77: Custo/ Peça P.Q | F77: Custo/ Kilo P.Q | H77: Linha 6 | I77: Custo/ Total | K77: Prod. Químico | M77: Linha 6 | N77: % | O77: Peça | P77: Kilo
B78: Zn Ní. Semi Aut. | C78: =I78/'Peças por Hora Galvanoplastia'!B51 -> 0 | D78: =I78/'Peças por Hora Galvanoplastia'!C51 -> 0 | E78: =K78/'Peças por Hora Galvanoplastia'!B51 -> 0.051581388 | F78: =K78/'Peças por Hora Galvanoplastia'!C51 -> 0.073687697 | H78: Zn Ní. Semi Aut. | I78: =IF(J78=1,HLOOKUP(G6,'Resumo de Custo'!DS7:ED15,7,0),0) -> 0 | J78: 1 | K78: =IF(J78=1,HLOOKUP(G6,'Resumo de Custo'!EF7:EQ15,7,0),0) -> 181.81818 | M78: Item | N78: 1 | O78: =C87 -> 0 | P78: =D87 -> 0
M79: Imposto Único | N79: 0.15 | O79: =O78*N79 -> 0 | P79: =P78*N79 -> 0
H86: Total | I86: =SUM(I78:I85) -> 0 | K86: =SUM(K78:K85) -> 181.81818
B87: Total | C87: =SUM(C78:C86) -> 0 | D87: =SUM(D78:D86) -> 0 | E87: =SUM(E78:E86) -> 0.051581388 | F87: =SUM(F78:F86) -> 0.073687697 | M87: Custo Liquido | O87: =SUM(O78:O86) -> 0 | P87: =SUM(P78:P86) -> 0
B90: Linha 9 | C90: Custo / Peça | D90: Custo/Kilo | E90: Custo/ Peça P.Q | F90: Custo/ Kilo P.Q | H90: Linha 9 | I90: Custo/ Total | K90: Prod. Químico | M90: Linha 9 | N90: % | O90: Peça | P90: Kilo
B91: Pré Trat. Fosfato | C91: =I91/'Peças por Hora Galvanoplastia'!B59 -> 0 | D91: =I91/'Peças por Hora Galvanoplastia'!C59 -> 0 | E91: =K91/'Peças por Hora Galvanoplastia'!B59 -> 0 | F91: =K91/'Peças por Hora Galvanoplastia'!C59 -> 0 | H91: Pré Trat. Fosfato | I91: =IF(J91=1,HLOOKUP(G6,'Resumo de Custo'!DS7:ED15,8,0),0) -> 0 | J91: 1 | K91: =IF(J91=1,HLOOKUP(G6,'Resumo de Custo'!EF7:EQ15,8,0),0) -> 0 | M91: Item | N91: 1 | O91: =C100 -> 0 | P91: =D100 -> 0
M92: Imposto Único | N92: 0.15 | O92: =O91*N92 -> 0 | P92: =P91*N92 -> 0
H99: Total | I99: =SUM(I91:I98) -> 0 | K99: =SUM(K91:K98) -> 0
A100: Jan | B100: Total | C100: =SUM(C91:C99) -> 0 | D100: =SUM(D91:D99) -> 0 | E100: =SUM(E91:E99) -> 0 | F100: =SUM(F91:F99) -> 0 | M100: Custo Liquido | O100: =SUM(O91:O99) -> 0 | P100: =SUM(P91:P99) -> 0
A101: Fev
A102: Mar
A103: Abr
...

Sheet Lnha 1 Zn Alc. Aut
A2: Menu
A3: Zn/Alcalino Rotativo Aut
E5: 45292 | F5: 45292 | G5: 45292 | H5: 45323 | I5: 45323 | J5: 45323 | K5: 45352 | L5: 45352 | M5: 45352 | N5: 45383 | O5: 45383 | P5: 45383 | Q5: 45413 | R5: 45413 | S5: 45413 | T5: 45444 | U5: 45444 | V5: 45444 | W5: 45474 | X5: 45474 | Y5: 45474 | Z5: 45505 | AA5: 45505 | AB5: 45505 | AC5: 45536 | AD5: 45536 | AE5: 45536 | AF5: 45566 | AG5: 45566 | AH5: 45566 | AI5: 45597 | AJ5: 45597 | AK5: 45597 | AL5: 45627 | AM5: 45627 | AN5: 45627
A6: Produto | B6: ID | C6: Volume tanque / lts | D6: Concentração g/lt | E6: Consumo Kg/lt | F6: Custo/Kg | G6: Custo Total | H6: Consumo Kg/lt | I6: Custo/Kg | J6: Custo Total | K6: Consumo Kg/lt | L6: Custo Kg/lt | M6: Custo Total | N6: Consumo Kg/lt | O6: Custo/Kg | P6: Custo Total | Q6: Consumo Kg/lt | R6: Custo/Kg | S6: Custo Total | T6: Consumo Kg/lt | U6: Custo/Kg | V6: Custo Total | W6: Consumo Kg/lt | X6: Custo/Kg | Y6: Custo Total | Z6: Consumo Kg/lt | AA6: Custo/Kg | AB6: Custo Total | AC6: Consumo Kg/lt | AD6: Custo/Kg | AE6: Custo Total | AF6: Consumo Kg/lt | AG6: Custo/Kg | AH6: Custo Total | AI6: Consumo Kg/lt | AJ6: Custo/Kg | AK6: Custo Total | AL6: Consumo Kg/lt | AM6: Custo/Kg | AN6: Custo Total
A7: Composto C-40 (soda cáustica) | C7: 5000 | D7: 0 | E7: 0 | F7: 0 | G7: =F7*E7 -> 0 | H7: 0 | I7: 0 | J7: =I7*H7 -> 0 | K7: 0 | L7: 0 | M7: =L7*K7 -> 0 | N7: 0 | O7: 0 | P7: =O7*N7 -> 0 | Q7: 0 | R7: 0 | S7: =R7*Q7 -> 0 | T7: 0 | U7: 0 | V7: =U7*T7 -> 0 | W7: 0 | X7: 0 | Y7: =X7*W7 -> 0 | Z7: 0 | AA7: 0 | AB7: =AA7*Z7 -> 0 | AC7: 200 | AD7: 0 | AE7: =AD7*AC7 -> 0 | AF7: 0 | AG7: 0 | AH7: =AG7*AF7 -> 0 | AI7: 0 | AJ7: 0 | AK7: =AJ7*AI7 -> 0 | AL7: 0 | AM7: 0 | AN7: =AM7*AL7 -> 0
A8: Zincoat Plus Carrier | D8: 0 | E8: 0 | F8: 0 | G8: =F8*E8 -> 0 | H8: 0 | I8: 0 | J8: =I8*H8 -> 0 | K8: 0 | L8: 0 | M8: =L8*K8 -> 0 | N8: 0 | O8: 0 | P8: =O8*N8 -> 0 | Q8: 0 | R8: 0 | S8: =R8*Q8 -> 0 | T8: 0 | U8: 0 | V8: =U8*T8 -> 0 | W8: 0 | X8: 0 | Y8: =X8*W8 -> 0 | Z8: 0 | AA8: 0 | AB8: =AA8*Z8 -> 0 | AC8: 100 | AD8: 0 | AE8: =AD8*AC8 -> 0 | AF8: 0 | AG8: 0 | AH8: =AG8*AF8 -> 0 | AI8: 0 | AJ8: 0 | AK8: =AJ8*AI8 -> 0 | AL8: 0 | AM8: 0 | AN8: =AM8*AL8 -> 0
A9: Zincoat Plus Brightener | D9: 0 | E9: 0 | F9: 0 | G9: =F9*E9 -> 0 | H9: 0 | I9: 0 | J9: =I9*H9 -> 0 | K9: 0 | L9: 0 | M9: =L9*K9 -> 0 | N9: 0 | O9: 0 | P9: =O9*N9 -> 0 | Q9: 0 | R9: 0 | S9: =R9*Q9 -> 0 | T9: 0 | U9: 0 | V9: =U9*T9 -> 0 | W9: 0 | X9: 0 | Y9: =X9*W9 -> 0 | Z9: 0 | AA9: 0 | AB9: =AA9*Z9 -> 0 | AC9: 100 | AD9: 0 | AE9: =AD9*AC9 -> 0 | AF9: 0 | AG9: 0 | AH9: =AG9*AF9 -> 0 | AI9: 0 | AJ9: 0 | AK9: =AJ9*AI9 -> 0 | AL9: 0 | AM9: 0 | AN9: =AM9*AL9 -> 0
A10: Spectra Matte 255 | C10: 300 | D10: 0 | E10: 0 | F10: 0 | G10: =F10*E10 -> 0 | H10: 0 | I10: 0 | J10: =I10*H10 -> 0 | K10: 0 | L10: 0 | M10: =L10*K10 -> 0 | N10: 0 | O10: 0 | P10: =O10*N10 -> 0 | Q10: 0 | R10: 0 | S10: =R10*Q10 -> 0 | T10: 0 | U10: 0 | V10: =U10*T10 -> 0 | W10: 0 | X10: 0 | Y10: =X10*W10 -> 0 | Z10: 0 | AA10: 0 | AB10: =AA10*Z10 -> 0 | AC10: 25 | AD10: 0 | AE10: =AD10*AC10 -> 0 | AF10: 0 | AG10: 0 | AH10: =AG10*AF10 -> 0 | AI10: 0 | AJ10: 0 | AK10: =AJ10*AI10 -> 0 | AL10: 0 | AM10: 0 | AN10: =AM10*AL10 -> 0
A11: Active MC-20 | C11: 300 | D11: 0 | E11: 0 | F11: 0 | G11: =F11*E11 -> 0 | H11: 0 | I11: 0 | J11: =I11*H11 -> 0 | K11: 0 | L11: 0 | M11: =L11*K11 -> 0 | N11: 0 | O11: 0 | P11: =O11*N11 -> 0 | Q11: 0 | R11: 0 | S11: =R11*Q11 -> 0 | T11: 0 | U11: 0 | V11: =U11*T11 -> 0 | W11: 0 | X11: 0 | Y11: =X11*W11 -> 0 | Z11: 0 | AA11: 0 | AB11: =AA11*Z11 -> 0 | AC11: 25 | AD11: 0 | AE11: =AD11*AC11 -> 0 | AF11: 0 | AG11: 0 | AH11: =AG11*AF11 -> 0 | AI11: 0 | AJ11: 0 | AK11: =AJ11*AI11 -> 0 | AL11: 0 | AM11: 0 | AN11: =AM11*AL11 -> 0
A12: Metal Clean FE 01 | C12: 500 | D12: 0 | E12: 0 | F12: 0 | G12: =F12*E12 -> 0 | H12: 0 | I12: 0 | J12: =I12*H12 -> 0 | K12: 0 | L12: 0 | M12: =L12*K12 -> 0 | N12: 0 | O12: 0 | P12: =O12*N12 -> 0 | Q12: 0 | R12: 0 | S12: =R12*Q12 -> 0 | T12: 0 | U12: 0 | V12: =U12*T12 -> 0 | W12: 0 | X12: 0 | Y12: =X12*W12 -> 0 | Z12: 0 | AA12: 0 | AB12: =AA12*Z12 -> 0 | AC12: 25 | AD12: 0 | AE12: =AD12*AC12 -> 0 | AF12: 0 | AG12: 0 | AH12: =AG12*AF12 -> 0 | AI12: 0 | AJ12: 0 | AK12: =AJ12*AI12 -> 0 | AL12: 0 | AM12: 0 | AN12: =AM12*AL12 -> 0
A13: Anodo | C13: 0 | D13: 0 | E13: 0 | F13: 0 | G13: =F13*E13 -> 0 | H13: 0 | I13: 0 | J13: =I13*H13 -> 0 | K13: 0 | L13: 0 | M13: =L13*K13 -> 0 | N13: 0 | O13: 0 | P13: =O13*N13 -> 0 | Q13: 0 | R13: 0 | S13: =R13*Q13 -> 0 | T13: 0 | U13: 0 | V13: =U13*T13 -> 0 | W13: 0 | X13: 0 | Y13: =X13*W13 -> 0 | Z13: 0 | AA13: 0 | AB13: =AA13*Z13 -> 0 | AC13: 200 | AD13: 0 | AE13: =AD13*AC13 -> 0 | AF13: 0 | AG13: 0 | AH13: =AG13*AF13 -> 0 | AI13: 0 | AJ13: 0 | AK13: =AJ13*AI13 -> 0 | AL13: 0 | AM13: 0 | AN13: =AM13*AL13 -> 0
C14: 0 | D14: 0 | E14: 0
F15: Total | G15: =SUM(G7:G14) -> 0 | I15: Total | J15: =SUM(J7:J14) -> 0 | L15: Total | M15: =SUM(M7:M14) -> 0 | O15: Total | P15: =SUM(P7:P14) -> 0 | R15: Total | S15: =SUM(S7:S14) -> 0 | U15: Total | V15: =SUM(V7:V14) -> 0 | X15: Total | Y15: =SUM(Y7:Y14) -> 0 | AA15: Total | AB15: =SUM(AB7:AB14) -> 0 | AD15: Total | AE15: =SUM(AE7:AE14) -> 0 | AG15: Total | AH15: =SUM(AH7:AH14) -> 0 | AJ15: Total | AK15: =SUM(AK7:AK14) -> 0 | AM15: Total | AN15: =SUM(AN7:AN14) -> 0

Sheet Linha 2 Zn Alc. Aut
A2: Menu
A3: Zn/Alcalino Rotativo Aut
E5: 45292 | F5: 45292 | G5: 45292 | H5: 45323 | I5: 45323 | J5: 45323 | K5: 45352 | L5: 45352 | M5: 45352 | N5: 45383 | O5: 45383 | P5: 45383 | Q5: 45413 | R5: 45413 | S5: 45413 | T5: 45444 | U5: 45444 | V5: 45444 | W5: 45474 | X5: 45474 | Y5: 45474 | Z5: 45505 | AA5: 45505 | AB5: 45505 | AC5: 45536 | AD5: 45536 | AE5: 45536 | AF5: 45566 | AG5: 45566 | AH5: 45566 | AI5: 45597 | AJ5: 45597 | AK5: 45597 | AL5: 45627 | AM5: 45627 | AN5: 45627
A6: Produto | B6: ID | C6: Volume tanque / lts | D6: Concentração /% | E6: Consumo Kg/lt | F6: Custo/Kg | G6: Custo Total | H6: Consumo Kg/lt | I6: Custo/Kg | J6: Custo Total | K6: Consumo Kg/lt | L6: Custo Kg/lt | M6: Custo Total | N6: Consumo Kg/lt | O6: Custo/Kg | P6: Custo Total | Q6: Consumo Kg/lt | R6: Custo/Kg | S6: Custo Total | T6: Consumo Kg/lt | U6: Custo/Kg | V6: Custo Total | W6: Consumo Kg/lt | X6: Custo/Kg | Y6: Custo Total | Z6: Consumo Kg/lt | AA6: Custo/Kg | AB6: Custo Total | AC6: Consumo Kg/lt | AD6: Custo/Kg | AE6: Custo Total | AF6: Consumo Kg/lt | AG6: Custo/Kg | AH6: Custo Total | AI6: Consumo Kg/lt | AJ6: Custo/Kg | AK6: Custo Total | AL6: Consumo Kg/lt | AM6: Custo/Kg | AN6: Custo Total
A7: Composto C-40 (soda cáustica) | C7: 5000 | D7: 0 | E7: 0 | F7: 0 | G7: =F7*E7 -> 0 | H7: 0 | I7: 0 | J7: =I7*H7 -> 0 | K7: 0 | L7: 0 | M7: =L7*K7 -> 0 | N7: 0 | O7: 0 | P7: =O7*N7 -> 0 | Q7: 0 | R7: 0 | S7: =R7*Q7 -> 0 | T7: 0 | U7: 1 | V7: =U7*T7 -> 0 | W7: 0 | X7: 0 | Y7: =X7*W7 -> 0 | Z7: 0 | AA7: 0 | AB7: =AA7*Z7 -> 0 | AC7: 200 | AD7: 0 | AE7: =AD7*AC7 -> 0 | AF7: 0 | AG7: 0 | AH7: =AG7*AF7 -> 0 | AI7: 0 | AJ7: 0 | AK7: =AJ7*AI7 -> 0 | AL7: 0 | AM7: 0 | AN7: =AM7*AL7 -> 0
A8: Zincoat Plus Carrier | D8: 0 | E8: 0 | F8: 0 | G8: =F8*E8 -> 0 | H8: 0 | I8: 0 | J8: =I8*H8 -> 0 | K8: 0 | L8: 0 | M8: =L8*K8 -> 0 | N8: 0 | O8: 0 | P8: =O8*N8 -> 0 | Q8: 0 | R8: 0 | S8: =R8*Q8 -> 0 | T8: 0 | U8: 0 | V8: =U8*T8 -> 0 | W8: 0 | X8: 0 | Y8: =X8*W8 -> 0 | Z8: 0 | AA8: 0 | AB8: =AA8*Z8 -> 0 | AC8: 100 | AD8: 0 | AE8: =AD8*AC8 -> 0 | AF8: 0 | AG8: 0 | AH8: =AG8*AF8 -> 0 | AI8: 0 | AJ8: 0 | AK8: =AJ8*AI8 -> 0 | AL8: 0 | AM8: 0 | AN8: =AM8*AL8 -> 0
A9: Zincoat Plus Brightener | D9: 0 | E9: 0 | F9: 0 | G9: =F9*E9 -> 0 | H9: 0 | I9: 0 | J9: =I9*H9 -> 0 | K9: 0 | L9: 0 | M9: =L9*K9 -> 0 | N9: 0 | O9: 0 | P9: =O9*N9 -> 0 | Q9: 0 | R9: 0 | S9: =R9*Q9 -> 0 | T9: 0 | U9: 0 | V9: =U9*T9 -> 0 | W9: 0 | X9: 0 | Y9: =X9*W9 -> 0 | Z9: 0 | AA9: 0 | AB9: =AA9*Z9 -> 0 | AC9: 100 | AD9: 0 | AE9: =AD9*AC9 -> 0 | AF9: 0 | AG9: 0 | AH9: =AG9*AF9 -> 0 | AI9: 0 | AJ9: 0 | AK9: =AJ9*AI9 -> 0 | AL9: 0 | AM9: 0 | AN9: =AM9*AL9 -> 0
A10: Spectra Matte 255 | C10: 300 | D10: 0 | E10: 0 | F10: 0 | G10: =F10*E10 -> 0 | H10: 0 | I10: 0 | J10: =I10*H10 -> 0 | K10: 0 | L10: 0 | M10: =L10*K10 -> 0 | N10: 0 | O10: 0 | P10: =O10*N10 -> 0 | Q10: 0 | R10: 0 | S10: =R10*Q10 -> 0 | T10: 0 | U10: 0 | V10: =U10*T10 -> 0 | W10: 0 | X10: 0 | Y10: =X10*W10 -> 0 | Z10: 0 | AA10: 0 | AB10: =AA10*Z10 -> 0 | AC10: 25 | AD10: 0 | AE10: =AD10*AC10 -> 0 | AF10: 0 | AG10: 0 | AH10: =AG10*AF10 -> 0 | AI10: 0 | AJ10: 0 | AK10: =AJ10*AI10 -> 0 | AL10: 0 | AM10: 0 | AN10: =AM10*AL10 -> 0
